File: Resultados Experimentales/TGA/Archivos Brutos/TGA 25C/Aire 25.txt
Method	Isothermal for
Size	25.9861	mg
Comment	ISAAC RADA
Xcomment	Pan: Alumina
Xcomment	Gas1: Nitrogen 0.0 ml/min
Xcomment	Gas2: Nitrogen 100.0 ml/min
Text
Exotherm	Up
Kcell	1.29300
InstCalDate	Weight: 2020-09-29  Time: 15:16:31 TempRange 78.86 to 1455.18 °C
InstCalFile	Weight: \\Iquieml784003\ta\Data\SDT\MTTO 2020 CA-LR\Beams vacios.001 \\Iquieml784003\ta\Data\SDT\MTTO 2020 CA-LR\Beams con masas.001
InstCalDate	Heat Flow: 2020-09-30  Time: 10:04:25 TempRange 108.00 to 1425.05 °C
InstCalFile	Heat Flow: \\Iquieml784003\ta\Data\SDT\MTTO 2020 CA-LR\Crisol vacio 2.001 \\Iquieml784003\ta\Data\SDT\MTTO 2020 CA-LR\Safiro hf.001
InstCalDate	DTA Baseline: 2020-09-30  Time: 11:25:31 TempRange 100.01 to 1464.76 °C
InstCalFile	DTA Baseline: \\Iquieml784003\ta\Data\SDT\MTTO 2020 CA-LR\Beams vacios.001
TempCal	4	pts	20.08	20.40,358.34	358.20,422.71	419.53,929.97	930.80
Controls	Gas 2  Event OFF  Sampling 0.5 sec/pt
AutoAnalysis	Off
MacroFile
Nsig	3
Sig1	Time (min)
Sig2	Temperature (°C)
Sig3	Weight (mg)
Date	2020-11-17
Time	08:50:50
OrgMethod	1: Equilibrate at 25.00 °C
OrgMethod	2: Isothermal for 1440.00 min
OrgFile	E:\DANIEL ROZO\Aire 25 (2).003
StartOfData
5.56E-04	23.38287	25.9861
0.1958334	24.10049	25.98604
0.3958334	24.69594	25.98596
0.5958334	25.15992	25.9857
0.7958334	25.5537	25.98554
0.9958332	25.85808	25.98535
1.195833	26.09312	25.9853
1.395834	26.27854	25.98501
1.595833	26.40167	25.98478
1.795834	26.49274	25.98453
1.995833	26.536	25.98437
2.195834	26.5492	25.98432
2.395833	26.55368	25.98418
2.595833	26.5024	25.98402
2.795834	26.46209	25.98368
2.995834	26.39186	25.98342
3.195834	26.30891	25.98336
3.395833	26.21328	25.98323
3.595833	26.11574	25.9832
3.795833	26.0155	25.98301
3.995834	25.90184	25.9829
4.195833	25.78319	25.98275
4.395834	25.65632	25.98254
4.595833	25.53833	25.98246
4.795833	25.40781	25.98234
4.995834	25.28512	25.98244
5.195833	25.16659	25.98218
5.879166	24.7496	25.98211
6.079168	24.62614	25.98189
6.279168	24.50699	25.98179
6.479166	24.3911	25.98167
6.679168	24.27434	25.98156
6.879166	24.1627	25.98159
7.079168	24.05394	25.98158
7.279166	23.93585	25.98152
7.479166	23.8237	25.98151
7.679168	23.728	25.98137
7.879166	23.61722	25.98137
8.079166	23.51256	25.98134
8.279166	23.41493	25.98118
8.479168	23.31697	25.98124
8.679168	23.2192	25.98116
8.879166	23.13009	25.98117
9.079166	23.04168	25.98106
9.279166	22.9545	25.981
9.479168	22.87997	25.98097
9.679168	22.81878	25.98077
9.879166	22.76008	25.98067
10.07917	22.72192	25.98087
10.27917	22.70005	25.98075
10.47917	22.70346	25.98075
10.67917	22.69963	25.98054
10.87916	22.71494	25.98055
11.07916	22.739	25.98046
11.27916	22.75504	25.98045
11.47917	22.76881	25.98046
11.67917	22.79614	25.98053
11.87916	22.81624	25.9803
12.07916	22.82916	25.98022
12.27916	22.84008	25.98046
12.47917	22.84688	25.98035
12.67917	22.85546	25.9803
12.87917	22.8534	25.98028
13.07916	22.85462	25.9801
13.27916	22.84442	25.97989
13.47917	22.84828	25.98012
13.67917	22.82439	25.98005
13.87917	22.8209	25.98004
14.07916	22.81911	25.97984
14.27916	22.80728	25.97973
14.47917	22.80683	25.97982
14.67917	22.79177	25.97973
14.87917	22.79565	25.97978
15.07916	22.79774	25.97979
15.27916	22.7977	25.97977
15.47917	22.79626	25.97954
15.67917	22.79242	25.97946
15.87917	22.7925	25.97954
16.07916	22.79747	25.97945
16.27917	22.79582	25.97951
16.47916	22.80382	25.97941
16.67917	22.80531	25.97932
16.87917	22.80873	25.97942
17.07916	22.8162	25.97922
17.27917	22.82055	25.97924
17.47916	22.83033	25.97929
17.67917	22.8158	25.97924
17.87917	22.8162	25.97912
18.07916	22.826	25.97902
18.27917	22.81804	25.97902
18.47916	22.81564	25.9791
18.67917	22.82306	25.97901
18.87917	22.81776	25.97897
19.07916	22.82139	25.97889
19.27917	22.81967	25.97878
19.47916	22.82394	25.97884
19.67917	22.81648	25.97897
19.87917	22.81252	25.97894
20.07916	22.81912	25.9789
20.27917	22.80735	25.97878
20.47916	22.81367	25.9787
20.67917	22.81424	25.97852
20.87917	22.80933	25.97857
21.07916	22.81433	25.97869
21.27917	22.80605	25.97854
21.47916	22.81936	25.97866
21.67917	22.82512	25.9787
21.87917	22.82678	25.97852
22.07916	22.82769	25.9785
22.27917	22.8211	25.97834
22.47916	22.82521	25.97826
22.67917	22.82997	25.97833
22.87917	22.8227	25.97852
23.07916	22.82978	25.9783
23.27917	22.83006	25.97821
23.47916	22.82658	25.97818
23.67917	22.82896	25.97818
23.87917	22.83523	25.97808
24.07916	22.84463	25.97808
24.27917	22.83081	25.97802
24.47916	22.8298	25.97814
24.67917	22.83418	25.97798
24.87917	22.8361	25.97777
25.07916	22.82135	25.97774
25.27917	22.82696	25.97788
25.47916	22.83136	25.97766
25.67916	22.83263	25.97739
25.87917	22.82854	25.9774
26.07916	22.83237	25.97746
26.27917	22.82291	25.97744
26.47916	22.82254	25.97752
26.67916	22.82838	25.97755
26.87917	22.823	25.97764
27.07916	22.81913	25.97762
27.27917	22.81949	25.97762
27.47916	22.82762	25.97777
27.67916	22.83287	25.97766
27.87917	22.8336	25.9775
28.07916	22.83906	25.97744
28.27917	22.84343	25.97738
28.47916	22.84242	25.97745
28.67916	22.84385	25.97735
28.87917	22.84297	25.97737
29.07916	22.84288	25.97737
29.27917	22.83925	25.97736
29.47916	22.83748	25.97734
29.67916	22.83936	25.9773
29.87917	22.83171	25.97714
30.07916	22.83137	25.97711
30.27917	22.83243	25.97735
30.47916	22.82612	25.97722
30.67916	22.83195	25.97717
30.87917	22.83079	25.9772
31.07916	22.83306	25.9771
31.27917	22.83106	25.97702
31.47916	22.83375	25.97703
31.67916	22.83093	25.97712
31.87917	22.83484	25.97708
32.07916	22.83786	25.97702
32.27917	22.8326	25.97686
32.47917	22.8371	25.97696
32.67916	22.83717	25.97694
32.87916	22.83882	25.97687
33.07916	22.82901	25.97704
33.27917	22.82047	25.97686
33.47917	22.8198	25.97684
33.67916	22.82132	25.9768
33.87916	22.82142	25.97674
34.07916	22.81584	25.97674
34.27917	22.82103	25.97671
34.47917	22.81667	25.97662
34.67916	22.82185	25.97672
34.87916	22.84675	25.97663
35.07916	22.83652	25.97662
35.27917	22.8424	25.97663
35.47917	22.84324	25.97649
35.67916	22.84646	25.9765
35.87916	22.85252	25.97653
36.07916	22.85138	25.97646
36.27917	22.85127	25.97653
36.47917	22.85122	25.97647
36.67916	22.85694	25.97654
36.87916	22.85142	25.97648
37.07916	22.84689	25.97632
37.27917	22.84292	25.97638
37.47917	22.83444	25.97631
37.67916	22.82804	25.97646
37.87916	22.82566	25.97638
38.07916	22.82979	25.97628
38.27917	22.83117	25.97615
38.47917	22.83342	25.97628
38.67916	22.83078	25.97628
38.87916	22.83164	25.9762
39.07916	22.83924	25.97616
39.27917	22.84262	25.97607
39.47917	22.84103	25.97613
39.67916	22.83754	25.97615
39.87916	22.83632	25.9762
40.07916	22.84332	25.97604
40.27917	22.8452	25.97602
40.47917	22.83991	25.97601
40.67916	22.84222	25.97598
40.87916	22.84056	25.97609
41.07916	22.84772	25.97591
41.27917	22.84967	25.97595
41.47917	22.85498	25.97597
41.67916	22.85361	25.97598
41.87916	22.86137	25.97581
42.07916	22.86924	25.97584
42.27917	22.86358	25.9759
42.47917	22.86927	25.97579
42.67916	22.84901	25.97586
42.87916	22.85299	25.97584
43.07916	22.84653	25.97582
43.27917	22.84504	25.9757
43.47917	22.84016	25.97572
43.67916	22.8361	25.9757
43.87916	22.82768	25.97573
44.07916	22.82016	25.97573
44.27917	22.82186	25.97565
44.47917	22.81541	25.97574
44.67916	22.82651	25.97556
44.87916	22.82137	25.97551
45.07916	22.82737	25.97537
45.27917	22.83864	25.97554
45.47917	22.83734	25.97566
45.67916	22.82976	25.97554
45.87916	22.83775	25.97533
46.07916	22.8239	25.97544
46.27917	22.81846	25.97538
46.47917	22.82322	25.97542
46.67916	22.82188	25.97536
46.87916	22.82854	25.97546
47.07916	22.83311	25.97544
47.27917	22.83544	25.97525
47.47917	22.84114	25.97546
47.67916	22.8458	25.97541
47.87916	22.84352	25.9752
48.07916	22.84782	25.97525
48.27917	22.84583	25.97512
48.47917	22.85398	25.9752
48.67916	22.84576	25.97518
48.87916	22.84429	25.97536
49.07916	22.84394	25.97528
49.27917	22.84715	25.97515
49.47917	22.85332	25.97507
49.67916	22.83854	25.9752
49.87916	22.84632	25.97494
50.07916	22.8531	25.97514
50.27917	22.84514	25.97508
50.47917	22.85514	25.97501
50.67916	22.84937	25.97512
50.87916	22.85856	25.97514
51.07916	22.85278	25.97508
51.27917	22.85151	25.97497
51.47917	22.85371	25.97495
51.67916	22.84839	25.97482
51.87916	22.84775	25.97486
52.07917	22.84773	25.97498
52.27917	22.84486	25.97499
52.47918	22.84743	25.97487
52.67916	22.84988	25.97481
52.87916	22.8471	25.97474
53.07918	22.83922	25.97468
53.27918	22.83927	25.97472
53.47918	22.84438	25.97467
53.67916	22.8335	25.97478
53.87916	22.84163	25.9748
54.07918	22.83945	25.97475
54.27918	22.8508	25.97467
54.47918	22.83856	25.9746
54.67916	22.84971	25.97461
54.87916	22.839	25.97466
55.07918	22.84028	25.97462
55.27918	22.84933	25.97486
55.47918	22.84289	25.97454
55.67916	22.83959	25.97464
55.87916	22.83953	25.97463
56.07918	22.83944	25.97448
56.27918	22.83706	25.9745
56.47918	22.82699	25.9744
56.67916	22.83608	25.97439
56.87916	22.83839	25.97456
57.07918	22.84026	25.97447
57.27918	22.85133	25.9745
57.47918	22.85849	25.97446
57.67916	22.85275	25.97442
57.87916	22.8492	25.97441
58.07918	22.85304	25.97434
58.27918	22.84954	25.97441
58.47918	22.84469	25.97433
58.67916	22.85355	25.97415
58.87916	22.84285	25.97435
59.07918	22.84247	25.97438
59.27918	22.8469	25.9743
59.47918	22.84384	25.97432
59.67916	22.83642	25.97399
59.87916	22.83905	25.97426
60.07918	22.84149	25.97424
60.27918	22.84938	25.97422
60.47918	22.8482	25.97431
60.67916	22.85942	25.97419
60.87916	22.8583	25.97403
61.07918	22.86538	25.97412
61.27918	22.85974	25.97412
61.47918	22.85668	25.97413
61.67916	22.86367	25.97422
61.87916	22.85812	25.97396
62.07918	22.85498	25.97409
62.27918	22.85108	25.9741
62.47918	22.84539	25.97401
62.67916	22.8471	25.97388
62.87916	22.83759	25.97378
63.07918	22.84635	25.97378
63.27918	22.83815	25.97395
63.47918	22.84187	25.97406
63.67916	22.83922	25.97392
63.87916	22.85071	25.97387
64.07918	22.84682	25.97383
64.27918	22.85882	25.97387
64.47916	22.86088	25.97386
64.67918	22.85855	25.97392
64.87916	22.86595	25.97373
65.07918	22.87266	25.97378
65.27918	22.8627	25.97384
65.47916	22.86614	25.97382
65.67918	22.85559	25.97378
65.87916	22.84651	25.97372
66.07918	22.84776	25.97368
66.27918	22.8339	25.97372
66.47916	22.83074	25.9736
66.67918	22.83244	25.97358
66.87916	22.82808	25.9737
67.07918	22.82568	25.97362
67.27918	22.82494	25.97358
67.47916	22.81845	25.97361
67.67918	22.82084	25.97358
67.87916	22.83092	25.97368
68.07918	22.83356	25.97364
68.27918	22.84338	25.97359
68.47916	22.85012	25.9736
68.67918	22.84701	25.97356
68.87916	22.86044	25.97358
69.07918	22.86842	25.97361
69.27918	22.85618	25.97354
69.47916	22.85787	25.97351
69.67918	22.86672	25.97357
69.87916	22.854	25.97338
70.07918	22.86633	25.97345
70.27918	22.8571	25.97334
70.47916	22.84881	25.97342
70.67918	22.85983	25.97317
70.87916	22.84475	25.97335
71.07918	22.84523	25.97331
71.27918	22.83701	25.97336
71.47916	22.84192	25.97331
71.67918	22.83886	25.97334
71.87916	22.8356	25.97336
72.07918	22.83887	25.97326
72.27918	22.8468	25.97324
72.47916	22.84146	25.97334
72.67918	22.83733	25.97317
72.87916	22.83897	25.97329
73.07918	22.8376	25.97322
73.27918	22.84668	25.97333
73.47916	22.84352	25.97324
73.67918	22.84381	25.97313
73.87916	22.84791	25.9732
74.07918	22.84616	25.97317
74.27918	22.84815	25.97323
74.47916	22.86048	25.97318
74.67918	22.8504	25.97334
74.87916	22.84254	25.97332
75.07918	22.85162	25.9731
75.27918	22.85403	25.97298
75.47916	22.85558	25.97286
75.67918	22.85601	25.97311
75.87916	22.85804	25.97319
76.07918	22.85402	25.97314
76.27918	22.8548	25.9731
76.47916	22.85392	25.97302
76.67918	22.84036	25.97294
76.87916	22.84868	25.97284
77.07918	22.84651	25.97294
77.27918	22.85474	25.97293
77.47916	22.8501	25.97298
77.67918	22.84881	25.97297
77.87916	22.85547	25.97288
78.07918	22.85054	25.97288
78.27918	22.8568	25.9729
78.47916	22.84765	25.97276
78.67918	22.84788	25.97288
78.87916	22.84352	25.97281
79.07918	22.84268	25.97286
79.27918	22.84764	25.97279
79.47916	22.85008	25.97269
79.67918	22.84725	25.97276
79.87916	22.85501	25.97274
80.07918	22.84725	25.97265
80.27918	22.86142	25.97274
80.47916	22.85149	25.97282
80.67918	22.86158	25.97272
80.87916	22.85296	25.97271
81.07918	22.84862	25.97268
81.27918	22.84652	25.9726
81.47916	22.86362	25.97266
81.67918	22.84878	25.97269
81.87916	22.83972	25.9726
82.07918	22.84244	25.97257
82.27918	22.8453	25.97262
82.47916	22.84961	25.97262
82.67918	22.85469	25.97265
82.87916	22.86226	25.97258
83.07918	22.85646	25.97266
83.27918	22.8652	25.97256
83.47916	22.85912	25.97256
83.67918	22.86221	25.97254
83.87916	22.86536	25.97232
84.07918	22.85911	25.97236
84.27918	22.85913	25.9725
84.47916	22.86046	25.97243
84.67918	22.858	25.97244
84.87916	22.84752	25.97252
85.07918	22.84126	25.97238
85.27918	22.8484	25.97246
85.47916	22.84475	25.97242
85.67918	22.852	25.9724
85.87916	22.84253	25.97239
86.07918	22.85172	25.97221
86.27918	22.85267	25.97251
86.47916	22.85167	25.97233
86.67918	22.85126	25.97242
86.87916	22.85282	25.97245
87.07918	22.85035	25.9724
87.27918	22.85944	25.97237
87.47916	22.85788	25.97232
87.67918	22.85339	25.97226
87.87916	22.85085	25.97236
88.07918	22.85912	25.97235
88.27918	22.85552	25.97221
88.47916	22.84064	25.97228
88.67918	22.84288	25.97219
88.87916	22.83556	25.97216
89.07918	22.84063	25.97222
89.27918	22.83655	25.97222
89.47916	22.83718	25.97228
89.67918	22.84222	25.97221
89.87916	22.8489	25.97212
90.07918	22.85871	25.97212
90.27918	22.84252	25.9722
90.47916	22.84886	25.97217
90.67918	22.85352	25.97215
90.87916	22.84844	25.97211
91.07918	22.8543	25.97208
91.27918	22.85243	25.97218
91.47916	22.85152	25.97216
91.67918	22.84667	25.97214
91.87916	22.85565	25.97198
92.07918	22.85378	25.9719
92.27918	22.8597	25.97186
92.47916	22.855	25.97204
92.67918	22.84975	25.97208
92.87916	22.84931	25.97202
93.07918	22.84644	25.97197
93.27918	22.84364	25.97164
93.47916	22.8425	25.9713
93.67918	22.84836	25.97154
93.87916	22.84232	25.97201
94.07918	22.83356	25.97224
94.27918	22.83406	25.97233
94.47916	22.8309	25.97198
94.67918	22.83356	25.97184
94.87916	22.8586	25.97172
95.07918	22.85142	25.97172
95.27918	22.86307	25.97172
95.47916	22.86325	25.97171
95.67918	22.87362	25.9718
95.87916	22.87825	25.97188
96.07918	22.87816	25.9719
96.27918	22.8793	25.9718
96.47916	22.87358	25.97183
96.67918	22.87584	25.97171
96.87916	22.87032	25.97169
97.07918	22.86875	25.97162
97.27918	22.86461	25.97171
97.47916	22.86089	25.9718
97.67918	22.84988	25.97185
97.87916	22.84671	25.97171
98.07918	22.84318	25.9718
98.27918	22.8455	25.97172
98.47916	22.83432	25.97161
98.67918	22.84411	25.97173
98.87916	22.85094	25.97159
99.07918	22.8523	25.97152
99.27918	22.85724	25.97173
99.47916	22.85419	25.97173
99.67918	22.85664	25.97164
99.87916	22.85808	25.97166
100.0792	22.85455	25.97155
100.2792	22.8545	25.97164
100.4792	22.85476	25.97184
100.6792	22.865	25.97164
100.8792	22.8576	25.97177
101.0792	22.86748	25.97173
101.2792	22.85945	25.97164
101.4792	22.86673	25.9716
101.6792	22.86778	25.97157
101.8792	22.86998	25.97162
102.0792	22.87473	25.97162
102.2792	22.87148	25.97166
102.4792	22.87008	25.97159
102.6792	22.87523	25.97167
102.8792	22.87424	25.97156
103.0792	22.86265	25.97148
103.2792	22.86901	25.97148
103.4792	22.86004	25.97149
103.6792	22.86319	25.9715
103.8792	22.86131	25.97149
104.0792	22.87336	25.9715
104.2792	22.85708	25.9714
104.4792	22.861	25.97154
104.6792	22.86965	25.97144
104.8792	22.86897	25.9715
105.0792	22.86041	25.97142
105.2792	22.86116	25.97136
105.4792	22.85803	25.97136
105.6792	22.848	25.97139
105.8792	22.84828	25.97134
106.0792	22.84294	25.97138
106.2792	22.8492	25.97138
106.4792	22.8502	25.97118
106.6792	22.84091	25.9713
106.8792	22.84367	25.97136
107.0792	22.84535	25.9712
107.2792	22.84848	25.9712
107.4792	22.84398	25.97124
107.6792	22.84701	25.97139
107.8792	22.84967	25.9714
108.0792	22.85616	25.97137
108.2792	22.85356	25.97142
108.4792	22.8472	25.97132
108.6792	22.85039	25.97122
108.8792	22.84572	25.97121
109.0792	22.85173	25.97124
109.2792	22.84385	25.97124
109.4792	22.83683	25.97136
109.6792	22.83995	25.97118
109.8792	22.84162	25.97115
110.0792	22.84472	25.9713
110.2792	22.85444	25.97125
110.4792	22.86345	25.97129
110.6792	22.859	25.97116
110.8792	22.86342	25.97113
111.0792	22.86298	25.97117
111.2792	22.8662	25.97122
111.4792	22.86508	25.97122
111.6792	22.87499	25.9713
111.8792	22.87942	25.97106
112.0792	22.88567	25.9711
112.2792	22.89423	25.97115
112.4792	22.88817	25.9712
112.6792	22.87534	25.97105
112.8792	22.87321	25.97098
113.0792	22.88207	25.97111
113.2792	22.86889	25.97098
113.4792	22.8602	25.97103
113.6792	22.85585	25.9711
113.8792	22.85734	25.9712
114.0792	22.8544	25.97113
114.2792	22.84998	25.97097
114.4792	22.85476	25.97102
114.6792	22.85344	25.97096
114.8792	22.85406	25.97094
115.0792	22.85106	25.97086
115.2792	22.85042	25.97107
115.4792	22.85008	25.97102
115.6792	22.85603	25.97106
115.8792	22.85906	25.97113
116.0792	22.85853	25.97098
116.2792	22.85632	25.97097
116.4792	22.85769	25.97088
116.6792	22.8554	25.971
116.8792	22.85446	25.97096
117.0792	22.84335	25.971
117.2792	22.84006	25.97085
117.4792	22.8561	25.97088
117.6792	22.84914	25.97076
117.8792	22.85632	25.97088
118.0792	22.85974	25.97106
118.2792	22.85566	25.97092
118.4792	22.85977	25.971
118.6792	22.8675	25.9708
118.8792	22.87874	25.9708
119.0792	22.8627	25.97078
119.2792	22.86241	25.97087
119.4792	22.86272	25.97081
119.6792	22.85865	25.9708
119.8792	22.86338	25.97086
120.0792	22.85502	25.97086
120.2792	22.8589	25.97092
120.4792	22.8592	25.97076
120.6792	22.85056	25.9709
120.8792	22.85505	25.97073
121.0792	22.84746	25.97089
121.2792	22.85386	25.97077
121.4792	22.85484	25.97096
121.6792	22.84717	25.97092
121.8792	22.8499	25.97074
122.0792	22.86135	25.97084
122.2792	22.85118	25.97077
122.4792	22.85362	25.97078
122.6792	22.87749	25.97075
122.8792	22.85594	25.9708
123.0792	22.86942	25.97072
123.2792	22.87702	25.97083
123.4792	22.85922	25.97076
123.6792	22.86307	25.97082
123.8792	22.86602	25.9707
124.0792	22.87256	25.97079
124.2792	22.87858	25.9709
124.4792	22.88064	25.97077
124.6792	22.87786	25.97074
124.8792	22.88099	25.97049
125.0792	22.86979	25.9704
125.2792	22.871	25.97042
125.4792	22.86959	25.97063
125.6792	22.86029	25.97084
125.8792	22.8557	25.97084
126.0792	22.85455	25.97084
126.2792	22.86984	25.97079
126.4792	22.85553	25.97071
126.6792	22.85586	25.97066
126.8792	22.85384	25.97055
127.0792	22.85555	25.97054
127.2792	22.85283	25.97056
127.4792	22.85866	25.97055
127.6792	22.85408	25.97074
127.8792	22.85738	25.97056
128.0792	22.84924	25.97074
128.2792	22.84892	25.97061
128.4792	22.85272	25.9704
128.6792	22.84675	25.97037
128.8792	22.84995	25.97032
129.0792	22.85918	25.97052
129.2792	22.85686	25.97042
129.4792	22.85926	25.97051
129.6792	22.85877	25.97062
129.8792	22.87057	25.97061
130.0792	22.86616	25.97056
130.2792	22.87172	25.97046
130.4792	22.86662	25.97044
130.6792	22.8664	25.97042
130.8792	22.86602	25.97042
131.0792	22.8658	25.97048
131.2792	22.86746	25.97054
131.4792	22.86434	25.97049
131.6792	22.86209	25.97052
131.8792	22.86472	25.97046
132.0792	22.85952	25.97052
132.2792	22.86088	25.97043
132.4792	22.86759	25.9704
132.6792	22.86522	25.97048
132.8792	22.86725	25.97044
133.0792	22.85756	25.97048
133.2792	22.85713	25.97044
133.4792	22.86054	25.97034
133.6792	22.86987	25.97038
133.8792	22.86229	25.97042
134.0792	22.86964	25.97051
134.2792	22.87836	25.9704
134.4792	22.8759	25.97046
134.6792	22.88116	25.97051
134.8792	22.87844	25.97044
135.0792	22.87375	25.97047
136.316667	24.07275	25.97057
139.041667	24.184	25.97056
140.858332	23.56511	25.97041
142.679168	22.9785	25.97039
144.5	22.82586	25.97043
146.31666	22.91408	25.97041
148.13333	22.87374	25.97039
149.95	22.84748	25.97018
151.76667	22.8542	25.97006
153.59166	22.88259	25.97018
155.40834	22.8733	25.97022
157.225	22.87145	25.97011
159.04167	22.86724	25.97013
160.85834	22.86098	25.97003
162.67917	22.86239	25.96998
164.5	22.87295	25.96981
166.31666	22.87361	25.96979
168.13334	22.88248	25.96975
169.95	22.87532	25.96972
171.76666	22.85454	25.96963
173.59166	22.87381	25.96957
175.40833	22.87014	25.96958
177.225	22.86424	25.96952
179.04167	22.8699	25.96945
180.85832	22.88224	25.96942
182.67916	22.86784	25.96933
184.5	22.87106	25.96928
186.31666	22.88821	25.96919
188.13334	22.88038	25.96916
189.95	22.86357	25.96906
191.76668	22.87723	25.96898
193.59166	22.87431	25.969
195.40834	22.89252	25.96895
197.225	22.8698	25.96879
199.04168	22.87141	25.96872
200.85832	22.87805	25.96866
202.67918	22.89414	25.96863
204.5	22.8682	25.96858
206.31668	22.86718	25.96849
208.13334	22.86777	25.96833
209.95	22.88557	25.96833
211.76666	22.87711	25.96823
213.59168	22.8848	25.96816
215.40834	22.87142	25.96811
217.225	22.8663	25.96799
219.04166	22.88762	25.96783
220.85832	22.88133	25.9678
222.67918	22.88753	25.96768
224.5	22.87965	25.96762
226.31666	22.87528	25.96755
228.13334	22.87376	25.96742
229.95	22.87273	25.96744
231.76666	22.88373	25.96721
233.59168	22.87462	25.96709
235.4083	22.87547	25.96703
237.225	22.87548	25.96699
239.0417	22.8883	25.96689
240.8583	22.89127	25.96677
242.6792	22.87716	25.96669
244.5	22.87215	25.96658
246.3167	22.89664	25.96643
248.1333	22.8908	25.96643
249.95	22.87594	25.96623
251.7667	22.8729	25.96611
253.5917	22.87182	25.96591
255.4083	22.86961	25.96588
257.225	22.87061	25.96581
259.0417	22.89226	25.96575
260.8583	22.8813	25.96561
262.6792	22.88166	25.96542
264.5	22.8745	25.96531
266.3167	22.88251	25.96523
268.1333	22.88347	25.96511
269.95	22.88652	25.96503
271.7667	22.87062	25.96486
273.5917	22.8702	25.96472
275.4083	22.892	25.96461
277.225	22.87258	25.96449
279.0417	22.86063	25.96417
280.8583	22.90614	25.96413
282.6791	22.88418	25.964
284.5	22.86943	25.96393
286.3167	22.876	25.96371
288.1333	22.87987	25.96354
289.95	22.88048	25.96347
291.7667	22.87596	25.9633
293.5917	22.8902	25.96317
295.4083	22.88297	25.96311
297.225	22.86179	25.96285
299.0417	22.87515	25.96277
300.8583	22.8752	25.96264
302.6791	22.88464	25.96246
304.5	22.87021	25.96223
306.3166	22.88025	25.9622
308.1333	22.89234	25.96201
309.95	22.85996	25.9618
311.7667	22.87686	25.96159
313.5916	22.86838	25.96151
315.4083	22.86675	25.96133
317.225	22.8992	25.96114
319.0417	22.88297	25.96105
320.8583	22.86011	25.96073
322.6791	22.88842	25.96066
324.5	22.87258	25.96054
326.3166	22.88106	25.96024
328.1333	22.88502	25.96013
329.95	22.87592	25.95989
331.7667	22.85485	25.95973
333.5916	22.88603	25.95956
335.4083	22.86131	25.95917
337.225	22.86493	25.95859
339.0417	22.8693	25.95835
340.8584	22.87806	25.95814
342.6791	22.87109	25.95796
344.5	22.88498	25.95781
346.3167	22.87988	25.95764
348.1333	22.85513	25.95739
349.95	22.88331	25.95723
351.7667	22.86946	25.95709
353.5917	22.88668	25.95697
355.4083	22.86568	25.95676
357.225	22.87338	25.95651
359.0417	22.87408	25.95638
360.8583	22.87368	25.95612
362.6791	22.86286	25.95597
364.5	22.88113	25.95581
366.3167	22.87499	25.95567
368.1333	22.86428	25.95548
369.95	22.88545	25.95523
371.7667	22.85687	25.95509
373.5917	22.87761	25.95494
375.4083	22.8707	25.95476
377.225	22.87138	25.95432
379.0417	22.86131	25.95445
380.8583	22.87964	25.95422
382.6791	22.87685	25.9541
384.5	22.87324	25.95385
386.3167	22.87894	25.95341
388.1333	22.85093	25.95355
389.95	22.89422	25.95337
391.7667	22.87274	25.95328
393.5917	22.86287	25.95306
395.4083	22.87111	25.95291
397.225	22.8665	25.95272
399.0417	22.86765	25.95255
400.8583	22.88698	25.95245
402.6792	22.86144	25.95229
404.5	22.8654	25.95223
406.3167	22.86783	25.95209
408.1333	22.87947	25.95187
409.95	22.87311	25.95167
411.7667	22.86864	25.95159
413.5916	22.89535	25.95147
415.4084	22.8648	25.95124
417.225	22.8833	25.95117
419.0417	22.86036	25.95112
420.8583	22.88035	25.95087
422.6792	22.87314	25.95085
424.5	22.85132	25.9506
426.3167	22.87012	25.9503
428.1333	22.8615	25.95023
429.95	22.88984	25.95007
431.7667	22.8783	25.95011
433.5916	22.86571	25.94991
435.4084	22.86145	25.94983
437.225	22.86534	25.94965
439.0417	22.86779	25.94951
440.8583	22.87082	25.94945
442.6792	22.88262	25.94934
444.5	22.86035	25.94925
446.3167	22.86836	25.94912
448.1333	22.86856	25.94895
449.95	22.88725	25.94889
451.7667	22.8749	25.94874
453.5916	22.88103	25.94857
455.4084	22.8562	25.94855
457.225	22.85214	25.94837
459.0417	22.86975	25.94831
460.8583	22.87216	25.9482
462.6792	22.87316	25.94807
464.5	22.86153	25.94792
466.3167	22.89778	25.94751
468.1333	22.87901	25.94719
469.95	22.8643	25.94706
471.7667	22.8661	25.94691
473.5916	22.84693	25.94685
475.4084	22.88123	25.94675
477.225	22.85187	25.94655
479.725	22.88682	25.94689
481.5417	22.87415	25.94683
483.3584	22.86053	25.94649
485.1792	22.86389	25.94625
487	22.86465	25.94597
488.8167	22.89195	25.94561
490.6333	22.87445	25.94552
492.45	22.85693	25.94528
494.2667	22.84502	25.94487
496.0916	22.88675	25.94469
497.9084	22.86967	25.94452
499.725	22.86632	25.94415
501.5417	22.87206	25.94409
503.3584	22.86996	25.94375
505.1792	22.86161	25.94359
507	22.8706	25.94339
508.8167	22.88198	25.94329
510.6333	22.85753	25.9431
512.45	22.8782	25.94283
514.2667	22.85216	25.94261
516.0916	22.8861	25.94249
517.9084	22.87152	25.94215
519.725	22.86438	25.94186
521.5417	22.85944	25.94189
523.3584	22.88434	25.94173
525.1792	22.88501	25.94144
527	22.8419	25.94114
528.8167	22.86544	25.94093
530.6333	22.87611	25.94069
532.45	22.86391	25.94045
534.2667	22.86785	25.94017
536.0916	22.88933	25.94011
537.9084	22.86016	25.93992
539.725	22.86496	25.93961
541.5417	22.8731	25.93944
543.3584	22.88115	25.93915
545.1792	22.85173	25.93904
547	22.86502	25.9387
548.8166	22.87032	25.93848
550.6333	22.87248	25.93832
552.45	22.88084	25.93793
554.2667	22.86382	25.93779
556.0916	22.84673	25.93757
557.9084	22.88262	25.9373
559.725	22.86218	25.93714
561.5417	22.87082	25.93677
563.3584	22.8716	25.93654
565.1792	22.8547	25.93635
567	22.86529	25.93618
568.8166	22.86627	25.93591
570.6333	22.88286	25.93575
572.45	22.8646	25.93546
574.2667	22.86213	25.93506
576.0916	22.8632	25.93494
577.9084	22.86214	25.93471
579.725	22.86938	25.93442
581.5417	22.87478	25.93434
583.3584	22.862	25.93387
585.1792	22.87054	25.93385
587	22.87169	25.93355
588.8166	22.86	25.93333
590.6333	22.86779	25.93295
592.45	22.87472	25.93278
594.2667	22.84945	25.93257
596.0916	22.85883	25.93242
597.9084	22.85953	25.93215
599.725	22.86388	25.93188
601.5417	22.84633	25.93166
603.3584	22.86964	25.93149
605.1792	22.86692	25.9311
607	22.87375	25.93106
608.8166	22.87092	25.93071
610.6333	22.86604	25.93044
612.45	22.85042	25.93027
614.2667	22.87342	25.93009
616.0916	22.87037	25.92999
617.9084	22.85572	25.92968
619.725	22.84818	25.92939
621.5417	22.8657	25.9292
623.3584	22.86292	25.92901
625.1792	22.85572	25.92875
627	22.85852	25.92847
628.8166	22.87991	25.92836
630.6333	22.86572	25.92812
632.45	22.84262	25.92779
634.2667	22.86033	25.92781
636.0916	22.87862	25.92731
637.9084	22.84926	25.92721
639.725	22.86842	25.92707
641.5417	22.85242	25.92679
643.3584	22.8804	25.9265
645.1792	22.86825	25.92633
647	22.85012	25.92607
648.8166	22.8609	25.92593
650.6334	22.85678	25.92567
652.45	22.8816	25.92551
654.2666	22.86437	25.92515
656.0916	22.85159	25.92494
657.9083	22.86221	25.92472
659.7249	22.85206	25.92455
661.5417	22.85897	25.92423
663.3583	22.86384	25.92417
665.1791	22.85426	25.92394
667	22.84989	25.92376
668.8166	22.85239	25.92347
670.6334	22.8631	25.92327
672.45	22.8462	25.92307
674.2666	22.89639	25.92295
676.0916	22.85455	25.9227
677.9083	22.85244	25.92243
679.7249	22.86146	25.92234
681.5417	22.84482	25.92225
683.3583	22.86756	25.922
685.1791	22.85224	25.92181
687	22.8528	25.92157
688.8166	22.85326	25.9214
690.6334	22.87184	25.92111
692.45	22.84366	25.92099
694.2666	22.85818	25.92072
696.0916	22.86063	25.92051
697.9083	22.85273	25.92037
699.7249	22.85742	25.92017
701.5417	22.85268	25.9199
703.3583	22.85357	25.9198
705.1791	22.87485	25.91961
707	22.84455	25.91944
708.8166	22.84843	25.91917
710.6334	22.86301	25.91895
712.45	22.86366	25.9187
714.2666	22.86058	25.91857
716.0916	22.8483	25.91839
717.9083	22.85211	25.91823
719.7249	22.84084	25.91797
721.5417	22.84968	25.9179
723.3583	22.86213	25.91766
725.1791	22.86517	25.91759
727.0001	22.85244	25.91727
728.8166	22.85028	25.91716
730.6334	22.86502	25.91688
732.45	22.85084	25.91671
734.2666	22.85685	25.91667
736.0916	22.848	25.91634
737.9083	22.84473	25.91631
739.7249	22.85657	25.91616
741.5417	22.85462	25.91603
743.3583	22.86076	25.9159
745.1791	22.84104	25.91569
747.0001	22.85842	25.9156
748.8166	22.86964	25.91539
750.6334	22.86418	25.91523
752.45	22.83808	25.91506
754.2666	22.83531	25.91492
756.0916	22.86345	25.91469
757.9083	22.84574	25.91454
759.7249	22.84232	25.9144
761.5417	22.87076	25.9143
763.3583	22.85184	25.91402
765.1791	22.83527	25.91389
767.0001	22.86085	25.91374
768.8166	22.87277	25.91356
770.6334	22.84264	25.9135
772.45	22.86116	25.91326
774.2666	22.84312	25.91301
776.0916	22.8529	25.91296
777.9083	22.84798	25.91284
779.7249	22.84702	25.91259
781.5417	22.8328	25.9125
783.3583	22.84615	25.91237
785.1791	22.85275	25.91207
787.0001	22.88039	25.91199
788.8166	22.82841	25.91193
790.6334	22.84626	25.91164
792.45	22.86864	25.91151
794.2666	22.84701	25.91139
796.0915	22.83917	25.91123
797.9083	22.85315	25.91101
799.7249	22.84217	25.91085
801.5417	22.84966	25.91075
803.3583	22.83633	25.91058
805.1791	22.87037	25.91043
807.0001	22.83211	25.91042
808.8166	22.85764	25.91004
810.6334	22.83907	25.90989
812.45	22.8451	25.90974
814.2666	22.85058	25.90963
816.0915	22.86447	25.90942
817.9083	22.83222	25.90933
819.7249	22.83987	25.90918
821.5417	22.8579	25.9088
823.3582	22.835	25.9087
825.1791	22.84337	25.90849
827.0001	22.86348	25.90843
828.8166	22.83011	25.90819
830.6335	22.84996	25.90805
832.45	22.85352	25.90789
834.2667	22.83778	25.90782
836.0915	22.86284	25.90769
837.9083	22.85396	25.90745
839.7249	22.83635	25.90731
841.5417	22.84979	25.90718
843.3582	22.8365	25.90704
845.1791	22.85861	25.90676
847.0001	22.83824	25.90669
848.8166	22.8359	25.90656
850.6335	22.8556	25.90634
852.45	22.85168	25.90611
854.2667	22.82509	25.90603
856.0915	22.83604	25.90585
857.9083	22.85509	25.9057
859.7249	22.83098	25.90552
861.5417	22.85468	25.90542
863.3582	22.85194	25.90528
865.1791	22.84129	25.90518
867.0001	22.85526	25.9051
868.8166	22.8592	25.90471
870.6335	22.83127	25.90481
872.45	22.85766	25.90461
874.2667	22.8433	25.90448
876.0915	22.83292	25.90427
877.9083	22.85573	25.90431
879.7249	22.81581	25.90399
881.5417	22.85362	25.90401
883.3582	22.85512	25.90378
885.1791	22.8348	25.90363
887.0001	22.83808	25.90359
888.8166	22.84677	25.90333
890.6335	22.83511	25.90319
892.45	22.84827	25.90311
894.2667	22.85572	25.903
896.0915	22.83864	25.90292
897.9083	22.83344	25.90279
899.7249	22.83925	25.90255
901.5417	22.84796	25.90247
903.3582	22.84387	25.90243
905.1791	22.83695	25.90223
907.0001	22.84218	25.90198
908.8166	22.8547	25.90203
910.6335	22.83669	25.90186
912.45	22.8412	25.90161
914.2667	22.84221	25.90157
916.0915	22.83287	25.90146
917.9083	22.84422	25.90128
919.7249	22.82667	25.90108
921.5417	22.85406	25.90106
923.3582	22.83402	25.9009
925.1791	22.83634	25.90089
927.0001	22.84155	25.90058
928.8166	22.83082	25.90059
930.6335	22.85006	25.90046
932.45	22.8318	25.90034
934.2667	22.83754	25.90035
936.0915	22.8402	25.90001
937.9083	22.83157	25.8999
939.7249	22.8492	25.89978
941.5417	22.83576	25.8996
943.3582	22.83615	25.89952
945.1791	22.8331	25.8994
947.0001	22.82801	25.89927
948.8166	22.83847	25.89906
950.6335	22.84402	25.89903
952.45	22.8339	25.89891
954.2667	22.8514	25.89874
956.0915	22.83191	25.89855
957.9085	22.84222	25.89851
959.7249	22.827	25.89838
961.5417	22.82687	25.89819
963.3582	22.84576	25.89815
965.1791	22.85608	25.89808
967	22.8314	25.8979
968.8165	22.82886	25.89783
970.6335	22.84306	25.89758
972.45	22.84992	25.89748
974.2667	22.83434	25.89749
976.0916	22.8274	25.89712
977.9084	22.83866	25.89711
979.7249	22.83496	25.89709
981.5417	22.83675	25.89691
983.3582	22.84302	25.89674
985.1791	22.84414	25.89669
987	22.81416	25.89645
988.8166	22.83208	25.89632
990.6334	22.83678	25.89641
992.45	22.8445	25.89629
994.2667	22.82906	25.89599
996.0916	22.82537	25.8961
997.9084	22.84597	25.89596
999.7249	22.82511	25.89583
1001.5417	22.8236	25.89561
1003.3582	22.83776	25.89553
1005.1791	22.84264	25.89542
1007	22.83366	25.89523
1008.8166	22.83401	25.89524
1010.6334	22.83232	25.89505
1012.45	22.82268	25.89486
1014.2667	22.82524	25.89491
1016.0916	22.84239	25.89474
1017.9084	22.84565	25.89452
1019.7249	22.82468	25.89437
1021.5417	22.82532	25.89431
1023.3582	22.83212	25.89423
1025.1791	22.8306	25.89407
1027	22.84783	25.89401
1028.8166	22.82698	25.8938
1030.6334	22.80875	25.8937
1032.45	22.84304	25.89362
1034.2667	22.82285	25.89351
1036.0916	22.83735	25.89331
1037.9084	22.83116	25.89324
1039.7249	22.84152	25.89311
1041.5417	22.81227	25.89304
1043.3582	22.82373	25.89303
1045.1791	22.82211	25.89284
1047	22.83583	25.89264
1048.8166	22.81976	25.89248
1050.6334	22.8543	25.89251
1052.45	22.83248	25.89237
1054.2667	22.82188	25.8922
1056.0916	22.82718	25.89206
1057.9084	22.82552	25.89193
1059.7249	22.8379	25.89193
1061.5417	22.82276	25.89165
1063.3582	22.83001	25.89166
1065.1793	22.83212	25.89149
1067	22.83837	25.89126
1068.8166	22.8262	25.89134
1070.6334	22.8092	25.89108
1072.45	22.84661	25.89103
1074.2667	22.82354	25.8909
1076.0916	22.83997	25.89086
1077.9084	22.82516	25.89071
1079.7249	22.82275	25.89055
1081.5417	22.82494	25.89056
1083.3582	22.81142	25.89033
1085.1793	22.84652	25.89036
1087	22.8315	25.8901
1088.8166	22.82088	25.88998
1090.6334	22.82278	25.88996
1092.45	22.83053	25.88967
1094.2667	22.82726	25.88961
1096.0916	22.82022	25.88944
1097.9084	22.8186	25.88936
1099.7249	22.82986	25.88939
1101.5417	22.83335	25.8892
1103.3582	22.83438	25.88905
1105.1793	22.8307	25.88901
1107	22.8155	25.88875
1108.8166	22.82477	25.88863
1110.6334	22.8336	25.88869
1112.45	22.8382	25.88859
1114.2667	22.81396	25.88847
1116.0916	22.82466	25.88842
1117.9084	22.81953	25.88824
1119.7249	22.8427	25.8882
1121.5417	22.81213	25.88805
1123.3582	22.82494	25.88801
1125.1793	22.82986	25.88789
1127	22.8285	25.88787
1128.8166	22.82002	25.88773
1130.6334	22.83256	25.88754
1132.45	22.81695	25.8876
1134.2667	22.83353	25.8874
1136.0915	22.83198	25.88729
1137.9085	22.82572	25.88725
1139.7245	22.81786	25.88707
1141.5415	22.82131	25.88691
1143.3585	22.81673	25.88697
1145.1795	22.82778	25.88689
1146.9995	22.82814	25.88669
1148.8165	22.82648	25.88659
1150.6335	22.84354	25.88652
1152.4495	22.8186	25.88628
1154.2665	22.82054	25.88652
1156.0915	22.82072	25.88624
1157.9085	22.81568	25.88619
1159.7245	22.82854	25.88618
1161.5415	22.82662	25.88605
1163.3585	22.8181	25.88588
1165.1795	22.8157	25.8858
1166.9995	22.8361	25.88572
1168.8165	22.84345	25.88567
1170.6335	22.80584	25.88561
1172.4495	22.81838	25.88552
1174.2665	22.82844	25.88531
1176.0915	22.81859	25.88535
1177.9085	22.81989	25.8852
1179.7245	22.82298	25.88503
1181.5415	22.8293	25.88495
1183.3585	22.82553	25.88473
1185.1795	22.82129	25.88479
1186.9995	22.82656	25.88477
1188.8165	22.83283	25.88466
1190.6335	22.82108	25.88447
1192.4495	22.8235	25.88445
1194.2665	22.83142	25.88431
1196.0915	22.81906	25.88426
1197.9085	22.81874	25.88413
1199.7245	22.83026	25.88401
1201.5415	22.83428	25.884
1203.3585	22.81176	25.88403
1205.1795	22.81975	25.88382
1206.9995	22.81639	25.88383
1208.8165	22.82238	25.88373
1210.6335	22.81275	25.88371
1212.4495	22.83502	25.88351
1214.2665	22.83059	25.88347
1216.0915	22.81652	25.88347
1217.9085	22.81288	25.8832
1219.7245	22.82453	25.88319
1221.5415	22.8108	25.88315
1223.3585	22.83061	25.88301
1225.1795	22.81748	25.88293
1226.9995	22.81836	25.88292
1228.8165	22.82696	25.88263
1230.6335	22.80901	25.88273
1232.4495	22.80769	25.88259
1234.2665	22.83127	25.88243
1236.0915	22.82618	25.88263
1237.9085	22.80991	25.88242
1239.7245	22.82205	25.88238
1241.5415	22.83174	25.88215
1243.3585	22.80446	25.88209
1245.1795	22.8269	25.88195
1246.9995	22.8079	25.882
1248.8165	22.82618	25.88193
1250.6335	22.82139	25.88176
1252.4495	22.81064	25.88178
1254.2665	22.81048	25.88172
1256.0915	22.83212	25.88156
1257.9085	22.82372	25.88157
1259.7245	22.83146	25.88143
1261.5415	22.81398	25.88134
1263.3585	22.80685	25.88122
1265.1795	22.82332	25.88121
1266.9995	22.80062	25.88102
1268.8165	22.82848	25.88096
1270.6335	22.82356	25.88107
1272.4495	22.808	25.8809
1274.2665	22.8165	25.88091
1276.0915	22.8252	25.88076
1277.9085	22.82798	25.88083
1279.7245	22.79692	25.88064
1281.5415	22.81803	25.88058
1283.3585	22.8222	25.88055
1285.1795	22.82353	25.88029
1286.9995	22.81032	25.88034
1288.8165	22.82142	25.88024
1290.6335	22.80382	25.88028
1292.4495	22.8261	25.88018
1294.2665	22.80647	25.88013
1296.0915	22.81902	25.88005
1297.9085	22.81419	25.87992
1299.7245	22.82539	25.87987
1301.5415	22.81606	25.87987
1303.3585	22.80301	25.87978
1305.1795	22.8315	25.87978
1306.9995	22.80471	25.87957
1308.8165	22.83246	25.87962
1310.6335	22.82384	25.87951
1312.4495	22.8135	25.87957
1314.2665	22.80111	25.87941
1316.0915	22.82791	25.8794
1317.9085	22.81959	25.87934
1319.7245	22.804	25.87924
1321.5415	22.81238	25.87925
1323.3585	22.81178	25.87919
1325.1795	22.82474	25.87903
1326.9995	22.82517	25.87906
1328.8165	22.81595	25.879
1330.6335	22.81317	25.87917
1332.4495	22.79742	25.87915
1334.2665	22.82847	25.87899
1336.0915	22.82242	25.87886
1337.9085	22.81403	25.87891
1339.7245	22.82314	25.87895
1341.5415	22.81066	25.87877
1343.3585	22.81094	25.87888
1345.1795	22.80066	25.87886
1346.9995	22.80918	25.87878
1348.8165	22.82378	25.87887
1350.6335	22.81828	25.87871
1352.4495	22.79542	25.8787
1354.2665	22.82445	25.87851
1356.0915	22.8144	25.87857
1357.9085	22.80698	25.87863
1359.7245	22.81357	25.87848
1361.5415	22.82677	25.87825
1363.3585	22.809	25.87841
1365.1795	22.79843	25.87815
1366.9995	22.81134	25.87807
1368.8165	22.82216	25.87811
1370.6335	22.80572	25.87814
1372.4495	22.81689	25.87804
1374.2665	22.8107	25.87791
1376.0915	22.81142	25.87801
1377.9085	22.80142	25.87793
1379.7245	22.81203	25.87794
1381.5415	22.82704	25.87796
1383.3585	22.80842	25.87788
1385.1795	22.80834	25.87781
1386.9995	22.8141	25.87783
1388.8165	22.80237	25.8777
1390.6335	22.81325	25.87774
1392.4495	22.81442	25.87777
1394.2665	22.80855	25.87778
1396.0915	22.8226	25.87777
1397.9085	22.81319	25.87776
1399.7245	22.80406	25.87786
1401.5415	22.8223	25.87773
1403.3585	22.81506	25.87777
1405.1795	22.81808	25.87779
1406.9995	22.81457	25.87784
1408.8165	22.8109	25.87788
1410.6335	22.82552	25.87778
1412.4495	22.81914	25.87785
1414.2665	22.8159	25.878
1416.0915	22.80424	25.87801
1417.9085	22.8083	25.87814
1419.7245	22.8291	25.87791
1421.5415	22.8088	25.8782
1423.3585	22.82606	25.87818
1425.1795	22.82658	25.87815
1426.9995	22.80038	25.87809
1428.8165	22.80516	25.87812
1430.6335	22.82877	25.87832
1432.4495	22.82278	25.87835
1434.2665	22.81688	25.87846
1436.0915	22.80825	25.87843
1437.9085	22.81033	25.87854
1439.7245	22.8255	25.87858
1441.5415	22.81616	25.87872
1443.3585	22.81114	25.87866
1445.1795	22.81883	25.87875
1446.9995	22.83573	25.87893
1448.8165	22.80877	25.87901
1450.6335	22.82795	25.87902
1452.4495	22.81876	25.87911
1454.2665	22.80623	25.87931
1456.0915	22.8294	25.87928
1457.9085	22.82213	25.8794
1459.7245	22.80639	25.87952
1461.5415	22.83132	25.87952
1463.3585	22.81863	25.8798
1465.1795	22.80728	25.87988
1466.9995	22.82353	25.88003
1468.8165	22.79931	25.88017
1470.6335	22.83124	25.88025
1472.4495	22.81867	25.88039
1474.2665	22.81116	25.8804
1476.0915	22.81751	25.88078
1477.9085	22.82802	25.88063
1479.7245	22.81718	25.88083
1481.5415	22.8218	25.88085
1483.3585	22.82152	25.88117
1485.1795	22.84145	25.88132
1486.9995	22.80157	25.8813
1488.8165	22.81476	25.88165
1490.6335	22.81352	25.88179
1492.4495	22.83728	25.88187
1494.2665	22.83508	25.88194
1496.0915	22.80128	25.88213
1497.9085	22.83888	25.88233
1499.7245	22.82552	25.8825
1501.5415	22.80514	25.88255
1503.3585	22.84222	25.88268
1505.1795	22.82834	25.8829
1506.9995	22.80866	25.88302
1508.8165	22.82435	25.88312
1510.6335	22.83175	25.88348
1512.4495	22.81369	25.8836
1514.2665	22.82536	25.88369
1516.0915	22.83075	25.88369
1517.9085	22.83184	25.88402
1519.7255	22.82272	25.88417
1521.5415	22.82642	25.88444
1523.3585	22.83549	25.88437
1525.1795	22.81336	25.88465
1526.9995	22.83106	25.88475
1528.8165	22.83684	25.885
1530.6335	22.82876	25.88515
1532.4495	22.82554	25.8852
1534.2665	22.82844	25.88542
1536.0915	22.82182	25.88561
1537.9085	22.82655	25.88571
1539.7255	22.83055	25.88564
1541.5415	22.83027	25.88615
1543.3585	22.84033	25.88615
1545.1795	22.81992	25.88644
1546.9995	22.82696	25.88645
1548.8165	22.8237	25.88678
1550.6335	22.83011	25.88685
1552.4495	22.83806	25.88728
1554.2665	22.83346	25.88732
1556.0915	22.83569	25.8874
1557.9085	22.83819	25.88739
1559.7255	22.8363	25.88773
1561.5415	22.82013	25.88788
1563.3585	22.84523	25.88809
1565.1795	22.82915	25.88824
1566.9995	22.83174	25.88857
1568.8165	22.8436	25.88869
1570.6335	22.84056	25.88873
1572.4495	22.82974	25.88879
1574.2665	22.82424	25.88902
1574.8005	22.83809	25.88909