File: Resultados Experimentales/TGA/Archivos Brutos/TGA 25C/Nitrogeno 25.txt
CLOSED
Version	2.0
Language	English
Run	1
RunSerial	2124
Instrument	SDT Q600 V20.9 Build 20
Module	DSC-TGA Standard
InstSerial	0600-1647
Operator	CA
File	\\Iquieml784003\ta\Data\SDT\2020\DANIEL ROZO\ACEITE DE LINAZA 25.001
Sample	ACEITE DE LINAZA 25
Size	27.7200	mg
ProcName	Isothermal for \\Iquieml784003\ta\QProcedures\SDT\procedimiento_daniel_rozo.prc
Method	Isothermal for
Comment	TESIS - DANIEL ROZO
Xcomment	Pan: Alumina
Xcomment	Gas1: Nitrogen 100.0 ml/min
Xcomment	Gas2: Nitrogen 0.0 ml/min
Text
Exotherm	Up
Kcell	1.29300
InstCalDate	Weight: 2020-09-29  Time: 15:16:31 TempRange 78.86 to 1455.18 °C
InstCalFile	Weight: \\Iquieml784003\ta\Data\SDT\MTTO 2020 CA-LR\Beams vacios.001 \\Iquieml784003\ta\Data\SDT\MTTO 2020 CA-LR\Beams con masas.001
InstCalDate	Heat Flow: 2020-09-30  Time: 10:04:25 TempRange 108.00 to 1425.05 °C
InstCalFile	Heat Flow: \\Iquieml784003\ta\Data\SDT\MTTO 2020 CA-LR\Crisol vacio 2.001 \\Iquieml784003\ta\Data\SDT\MTTO 2020 CA-LR\Safiro hf.001
InstCalDate	DTA Baseline: 2020-09-30  Time: 11:25:31 TempRange 100.01 to 1464.76 °C
InstCalFile	DTA Baseline: \\Iquieml784003\ta\Data\SDT\MTTO 2020 CA-LR\Beams vacios.001
TempCal	4	pts	20.08	20.40,358.34	358.20,422.71	419.53,929.97	930.80
Controls	Gas 1  Event OFF  Sampling 0.5 sec/pt
AutoAnalysis	Off
MacroFile
Nsig	3
Sig1	Time (min)
Sig2	Temperature (°C)
Sig3	Weight (mg)
Date	2020-10-14
Time	07:42:26
OrgMethod	1: Equilibrate at 25.00 °C
OrgMethod	2: Isothermal for 1440.00 min
OrgFile	E:\DANIEL ROZO\Nitrogeno 25.001
StartOfData
0.004166667	22.37538	27.71954
0.9541666	24.03877	27.71911
1.9375	24.65453	27.71859
2.920834	24.73448	27.71787
3.904167	24.5699	27.7173
4.8875	24.30303	27.71675
5.875	24.01252	27.71618
6.8625	23.71962	27.71572
7.845834	23.45336	27.71522
8.829166	23.21466	27.71478
9.8125	22.99846	27.71438
10.79583	22.82985	27.71417
11.7875	22.72832	27.71374
12.77083	22.71686	27.71348
13.75417	22.74035	27.71323
14.7375	22.74938	27.71298
15.72084	22.72853	27.71272
16.70834	22.73053	27.71254
17.69583	22.73166	27.71235
18.67917	22.75858	27.71213
19.6625	22.76652	27.71204
20.64584	22.76424	27.7118
21.62917	22.76652	27.71164
22.62083	22.77883	27.71154
23.60417	22.78667	27.71144
24.5875	22.78389	27.71134
25.57083	22.78164	27.71124
26.55416	22.77618	27.71104
27.54167	22.78057	27.71094
28.52917	22.80116	27.71084
29.5125	22.80147	27.71085
30.49583	22.81646	27.71074
31.47917	22.80416	27.71067
32.4625	22.80198	27.71066
33.45416	22.8007	27.7106
34.4375	22.79976	27.71066
35.42084	22.79179	27.71056
36.40417	22.8011	27.71048
37.3875	22.83818	27.71046
38.375	22.84923	27.71035
39.3625	22.83532	27.71041
40.34583	22.82101	27.71044
41.32916	22.80464	27.71036
42.3125	22.80772	27.71043
43.29584	22.8118	27.71044
44.2875	22.82157	27.71039
45.27083	22.83734	27.71038
46.25417	22.85347	27.7105
47.2375	22.84938	27.7104
48.22082	22.8367	27.71049
49.20833	22.82957	27.71058
50.19583	22.83721	27.71058
51.17916	22.84517	27.71058
52.1625	22.84941	27.71056
53.14584	22.85514	27.71062
54.12918	22.85738	27.7107
55.12084	22.86388	27.71075
56.10416	22.85583	27.71084
57.0875	22.85627	27.71089
58.07082	22.84537	27.71086
59.05416	22.84491	27.711
60.04168	22.86429	27.71105
61.02918	22.87314	27.71104
62.0125	22.86971	27.71118
62.99584	22.87192	27.71115
63.97916	22.8713	27.71126
64.9625	22.86859	27.71125
65.95416	22.8778	27.71132
66.9375	22.87198	27.71144
67.92084	22.86509	27.71152
68.90418	22.86548	27.71152
69.8875	22.8636	27.71166
70.875	22.8637	27.71175
71.8625	22.8647	27.71182
72.84582	22.88265	27.71185
73.82918	22.89086	27.71194
74.8125	22.87393	27.71203
75.79584	22.87249	27.71216
76.7875	22.8736	27.7122
77.77084	22.87864	27.71232
78.75416	22.87497	27.7123
80.27084	22.89269	27.71238
81.25416	22.87834	27.7124
82.2375	22.86153	27.71255
83.22082	22.87294	27.71268
84.20834	22.87048	27.71268
85.19582	22.88358	27.71278
86.17916	22.88184	27.71258
87.16251	22.89398	27.7129
88.14582	22.88629	27.713
89.12916	22.89223	27.71304
90.12084	22.89189	27.71312
91.10416	22.89183	27.7132
92.0875	22.89958	27.71334
93.07084	22.89826	27.71346
94.05416	22.89466	27.71346
95.04168	22.89245	27.7135
96.02918	22.88806	27.71362
97.0125	22.88862	27.71366
97.99584	22.89416	27.71377
98.97916	22.89566	27.7137
99.9625	22.89682	27.71381
100.9542	22.91075	27.71394
101.9375	22.9044	27.71405
102.9208	22.9042	27.71409
103.9042	22.90808	27.71424
104.8875	22.90738	27.71424
105.875	22.90193	27.71443
106.8625	22.88266	27.71439
107.8458	22.8902	27.71455
108.8292	22.8951	27.71454
109.8125	22.90918	27.71468
110.7958	22.90234	27.7147
111.7875	22.89683	27.7148
112.7708	22.89536	27.7149
113.7542	22.8986	27.71492
114.7375	22.88674	27.71494
115.7208	22.88504	27.71508
116.7084	22.88925	27.71511
117.6958	22.90054	27.71514
118.6792	22.90495	27.71514
119.6625	22.90117	27.71534
120.6458	22.90497	27.71546
121.6292	22.90804	27.7155
122.6208	22.8923	27.71546
123.6042	22.90127	27.71552
124.5875	22.89373	27.7157
125.5708	22.89577	27.7157
126.5542	22.90337	27.71576
127.5417	22.91287	27.71587
128.5292	22.9019	27.7159
129.5125	22.89854	27.71596
130.4958	22.8911	27.71599
131.4792	22.89513	27.71612
132.4625	22.89509	27.71604
133.4542	22.89766	27.71621
134.4375	22.90872	27.71628
135.4208	22.90801	27.71634
136.4042	22.90941	27.71621
137.3875	22.91847	27.7164
138.375	22.91554	27.71652
139.3625	22.91409	27.71647
140.3458	22.91238	27.71654
141.3292	22.9143	27.7166
142.3125	22.92612	27.71662
143.2958	22.9386	27.71664
144.2875	22.92578	27.71682
145.2708	22.9141	27.71684
146.2542	22.90006	27.71687
147.2375	22.89826	27.71687
148.2208	22.91497	27.71698
149.2084	22.93568	27.71706
150.1958	22.93432	27.71704
151.1792	22.9219	27.71709
152.1625	22.91836	27.71719
153.1458	22.91701	27.71727
154.1292	22.91852	27.71719
155.1208	22.92387	27.71733
156.1042	22.9246	27.71738
157.0875	22.92824	27.71742
158.0708	22.92638	27.71739
159.0542	22.93385	27.71757
160.0416	22.92374	27.71753
161.0292	22.91564	27.71756
162.0125	22.92642	27.71756
162.9958	22.92795	27.71761
163.9791	22.93903	27.71769
164.9625	22.93808	27.71784
165.9542	22.93901	27.71778
166.9375	22.93617	27.71782
167.9208	22.92025	27.71787
168.9042	22.92655	27.71792
169.8875	22.93388	27.71789
170.875	22.92331	27.71803
171.8625	22.9176	27.71802
172.8458	22.91628	27.71804
173.8291	22.93058	27.71813
174.8125	22.92964	27.71809
175.7958	22.92139	27.71816
176.7875	22.93086	27.71824
177.7708	22.92994	27.71827
178.7542	22.94148	27.71832
179.7375	22.95203	27.71833
180.7208	22.95724	27.71839
181.7083	22.93522	27.71839
182.6959	22.92756	27.7184
183.6791	22.92403	27.71832
184.6625	22.9289	27.71848
185.6458	22.92505	27.71856
186.6292	22.93452	27.71849
187.6208	22.93298	27.71856
188.6042	22.94808	27.7186
189.5875	22.93857	27.71855
190.5709	22.94848	27.71872
191.5541	22.95133	27.71876
192.5416	22.93946	27.71871
193.5292	22.93357	27.71878
194.5125	22.93335	27.7188
195.4958	22.93672	27.71884
196.4792	22.94032	27.71874
197.4625	22.93907	27.71888
198.4541	22.94507	27.71899
199.4375	22.95549	27.71904
200.4208	22.96289	27.71902
201.4042	22.95628	27.71901
202.3875	22.94171	27.71906
203.375	22.91588	27.71908
204.3625	22.901	27.7191
205.3459	22.91475	27.71912
206.3291	22.92067	27.71914
207.3125	22.93111	27.71918
208.2958	22.92968	27.71924
209.2875	22.94272	27.71935
210.2708	22.94522	27.71925
211.2542	22.95143	27.71924
212.2375	22.94764	27.71934
213.2208	22.95439	27.71934
214.2084	22.94656	27.7193
215.1958	22.94504	27.7194
216.1792	22.94265	27.71939
217.1625	22.93935	27.71949
218.1458	22.9499	27.71946
219.1292	22.95627	27.7195
220.1208	22.96873	27.71953
221.1042	22.96571	27.71954
222.0875	22.96419	27.71964
223.0708	22.95524	27.71968
224.0542	22.949	27.71966
225.0416	22.95103	27.71974
226.0292	22.94436	27.71978
227.0125	22.95742	27.71973
227.9958	22.95285	27.7199
228.9792	22.96034	27.71974
229.9625	22.96054	27.71987
230.9542	22.96455	27.71995
231.9375	22.969	27.71982
232.9208	22.96847	27.71994
233.9042	22.96813	27.71994
234.8875	22.96453	27.72002
235.875	22.95684	27.7201
236.8625	22.95882	27.72011
237.8458	22.95537	27.72013
238.8292	22.95204	27.72018
239.8125	22.95152	27.72015
240.7958	22.96046	27.72009
241.7875	22.95832	27.72025
242.7708	22.95138	27.72029
243.7542	22.96081	27.72031
244.7375	22.96342	27.7203
245.7208	22.96894	27.72025
246.7083	22.97206	27.72041
247.6958	22.9654	27.72038
248.6792	22.96934	27.72042
249.6625	22.9748	27.72051
250.6458	22.96588	27.72042
251.6292	22.95719	27.7205
252.6208	22.94663	27.72052
253.6042	22.95	27.72059
254.5875	22.96906	27.72053
255.5708	22.96164	27.72058
256.5542	22.9618	27.72061
257.5417	22.96304	27.72066
258.5292	22.96828	27.7206
259.5125	22.96961	27.72073
260.4958	22.98472	27.72071
261.4792	22.97701	27.72066
262.4625	22.9667	27.72076
263.4541	22.96629	27.7209
264.4375	22.96326	27.72082
265.4209	22.96765	27.72084
266.4042	22.9745	27.72088
267.3875	22.9711	27.72087
268.375	22.96767	27.72101
269.3625	22.96862	27.72102
270.3458	22.95318	27.72102
271.3291	22.96411	27.72102
272.3125	22.9587	27.72108
273.2959	22.95034	27.72104
274.2875	22.9632	27.72104
275.2709	22.98256	27.72106
276.2542	22.97678	27.72111
277.2375	22.95454	27.72112
278.2208	22.96505	27.72112
279.2084	22.95572	27.72111
280.1958	22.94768	27.72119
281.1792	22.96108	27.72131
282.1625	22.96864	27.72115
283.1459	22.97249	27.72124
284.1292	22.97146	27.7212
285.1208	22.97622	27.7213
286.1042	22.97618	27.72135
287.0875	22.97466	27.72126
288.0708	22.97452	27.7213
289.0542	22.98465	27.72138
290.0417	22.98282	27.72134
291.0292	22.97453	27.72128
292.0125	22.9704	27.72134
292.9958	22.97774	27.72143
293.9792	22.9773	27.72145
294.9625	22.9733	27.72142
295.9541	22.9747	27.72141
296.9375	22.97495	27.72152
297.9209	22.9644	27.72152
298.9042	22.96496	27.72142
299.8875	22.96128	27.72145
300.875	22.96401	27.7216
301.8625	22.96433	27.7215
302.8458	22.95658	27.72158
303.8291	22.97857	27.7216
304.8125	22.97269	27.72158
305.7959	22.96874	27.72158
306.7875	22.97087	27.72159
307.7709	22.97008	27.72154
308.7542	22.97976	27.7216
309.7375	22.98339	27.72154
310.7208	22.985	27.72157
311.7084	22.98615	27.72164
312.6958	22.98206	27.72162
313.6792	22.97547	27.72164
314.6625	22.97375	27.7217
315.6459	22.96166	27.72154
316.6292	22.95963	27.72168
317.6208	22.96662	27.72164
318.6042	22.96934	27.72164
319.5875	22.97603	27.72169
320.5708	22.97302	27.7216
321.5542	22.97896	27.72164
322.5417	22.98636	27.72164
323.5292	22.98934	27.72165
324.5125	22.98494	27.72161
325.4958	22.97576	27.7217
326.4792	22.97124	27.72163
327.4625	22.98237	27.72167
328.4541	22.976	27.72161
329.4375	22.987	27.72166
330.4209	22.9828	27.72161
331.4042	22.98106	27.7216
332.3875	22.97356	27.72171
333.375	22.98092	27.72174
334.3625	22.98953	27.72162
335.3458	22.99494	27.72173
336.3291	22.98425	27.7217
337.3125	22.98048	27.72159
338.2959	22.96422	27.72169
339.2875	22.96753	27.72173
340.2709	22.96683	27.72167
341.2542	22.96067	27.72167
342.2375	22.96962	27.72177
343.2209	22.97867	27.72172
344.2083	22.97947	27.7217
345.1958	22.98622	27.72173
346.1792	22.98116	27.72176
347.1625	22.9803	27.7218
348.1459	22.9845	27.72166
349.1292	22.97524	27.72183
350.1208	22.97995	27.72175
351.1042	22.99394	27.72186
352.0875	22.9848	27.72176
353.0708	22.97584	27.72179
354.0542	22.97765	27.72192
355.0417	22.98444	27.72174
356.0292	22.98914	27.72183
357.0125	22.99938	27.72179
357.9958	23.00285	27.72184
358.9792	23.00087	27.7218
359.9625	22.9966	27.72187
360.9541	23.00122	27.72187
361.9375	23.00564	27.72188
362.9209	22.98862	27.72186
363.9042	23.00138	27.72188
364.8875	22.99488	27.72188
365.875	22.98103	27.72187
366.8625	22.97393	27.72198
367.8459	22.97194	27.72192
368.8291	22.97792	27.72188
369.8125	22.9778	27.72198
370.7959	22.9855	27.72206
371.7875	22.98871	27.72194
372.7709	22.9828	27.72192
373.7542	22.98474	27.72194
374.7375	22.98691	27.722
375.7209	22.98824	27.72192
376.7083	22.99156	27.72193
377.6958	22.99117	27.72197
378.6792	22.99543	27.72198
379.6625	22.99432	27.72196
380.6459	22.9939	27.72199
381.6292	22.99334	27.72193
382.6208	22.99347	27.7219
383.6042	22.9908	27.72195
384.5875	22.9902	27.7219
385.5708	22.98791	27.72206
386.5542	22.9973	27.72193
387.5417	22.99552	27.72194
388.5292	22.99741	27.72186
389.5125	22.99639	27.72199
390.4958	22.99773	27.722
391.4792	22.99527	27.72196
392.4625	22.99305	27.72196
393.4541	22.9791	27.72198
394.4375	22.96673	27.72198
395.4209	22.9632	27.72197
396.4042	22.96826	27.72189
397.3875	22.96906	27.72184
398.375	22.96217	27.72186
399.3625	22.97746	27.72182
400.3459	22.98274	27.72186
401.3291	22.98173	27.72189
402.3125	22.98273	27.72168
403.2959	22.98117	27.72194
404.2875	22.9758	27.72178
405.2709	22.98026	27.7218
406.2542	22.98306	27.7218
407.2375	22.98121	27.72174
408.2209	22.98436	27.7218
409.2083	22.99121	27.72176
410.1959	22.99652	27.72176
411.1791	22.99516	27.7218
412.1625	22.98848	27.72172
413.1459	23.00015	27.7217
414.1292	22.99772	27.72164
415.1208	22.98749	27.72166
416.1042	22.99324	27.72168
417.0875	22.9799	27.72164
418.0709	22.97645	27.72166
419.0541	22.97497	27.72168
420.0417	22.96486	27.72166
421.0292	22.96565	27.72166
422.0125	22.97114	27.72151
422.9958	22.9854	27.72164
423.9792	22.98619	27.72163
424.9625	22.98606	27.72168
425.9541	22.98685	27.72162
426.9375	22.9809	27.72166
427.9209	22.968	27.72177
428.9042	22.96057	27.72164
429.8875	22.97058	27.72151
430.875	22.98502	27.72164
431.8625	22.99361	27.72164
432.8459	22.9981	27.72156
433.8291	22.99575	27.72164
434.8125	22.99619	27.7215
435.7959	22.99642	27.72164
436.7875	22.99548	27.72152
437.7709	23.0103	27.72161
438.7542	23.00869	27.72152
439.7375	23.00318	27.72144
440.7209	22.99012	27.72154
441.7083	22.97692	27.72146
442.6959	22.98023	27.72158
443.6791	22.98166	27.72144
444.6625	22.99117	27.7215
445.6459	22.99713	27.72146
446.6292	22.99588	27.72148
447.6208	22.9826	27.72144
448.6042	22.97712	27.72148
449.5875	22.98164	27.72149
450.5709	22.9808	27.72151
451.5541	22.98296	27.72145
452.5417	22.98568	27.72136
453.5292	22.98344	27.72141
454.5125	22.9896	27.72134
455.4958	22.99219	27.72142
456.4792	22.99479	27.72144
457.4625	22.99471	27.72139
458.4541	22.99792	27.72138
459.4375	22.99426	27.72145
460.4209	22.99678	27.72139
461.4042	23.00338	27.72133
462.3875	22.98977	27.72135
463.375	22.97198	27.72137
464.3625	22.97898	27.72136
465.3459	22.98922	27.72138
466.3291	23.00206	27.72145
467.3125	23.00523	27.72142
468.2959	23.00258	27.72142
469.2875	22.99513	27.72142
470.2709	22.98822	27.72136
471.2542	22.96864	27.72134
472.2375	22.96848	27.72136
473.2209	22.96871	27.72134
474.2083	22.96821	27.72132
475.1959	22.98618	27.72133
476.1791	22.99883	27.72139
477.1625	22.997	27.7213
478.1459	22.98905	27.72133
479.1292	22.98461	27.72134
480.1208	22.98243	27.72134
481.1042	22.98179	27.72129
482.0875	22.97643	27.72131
483.0709	22.98468	27.72133
484.0541	22.98183	27.72124
485.0417	22.97308	27.7212
486.0292	22.96796	27.72119
487.0125	22.96265	27.72117
487.9958	22.96302	27.72119
488.9792	22.969	27.72122
489.9625	22.97054	27.72104
490.9541	22.96883	27.72111
491.9375	22.98506	27.72108
492.9209	22.99545	27.72085
493.9042	22.9837	27.72085
494.8875	22.97564	27.72082
495.875	22.96795	27.7208
496.8625	22.96438	27.72075
497.8459	22.97594	27.72067
498.8291	22.98339	27.72064
499.8125	22.97412	27.72056
500.7959	22.98655	27.72061
501.7875	22.99598	27.72059
502.7709	22.99552	27.72046
503.7542	22.99637	27.72052
504.7375	22.98644	27.72039
505.7209	22.97558	27.72046
506.7083	22.96191	27.72032
507.6959	22.97194	27.72035
508.6791	22.96304	27.72025
509.6625	22.9619	27.72028
510.6459	22.95262	27.72016
511.6292	22.9604	27.72019
512.6209	22.96111	27.72003
513.6042	22.94933	27.72007
514.5874	22.94344	27.72009
515.5708	22.9488	27.71994
516.5541	22.95642	27.71988
517.5416	22.96018	27.71994
518.5292	22.96166	27.71976
519.5125	22.95256	27.71974
520.4959	22.95326	27.71958
521.4792	22.95648	27.71964
522.4624	22.95805	27.7196
523.4541	22.95481	27.71963
524.4375	22.96164	27.71946
525.4209	22.96106	27.7195
526.4042	22.95376	27.71938
527.3875	22.96406	27.71928
528.375	22.95871	27.71923
529.3625	22.94504	27.7192
530.3458	22.938	27.71914
531.3291	22.93385	27.71909
532.3125	22.93571	27.71896
533.2959	22.945	27.71893
534.2875	22.95092	27.71898
535.2708	22.94824	27.71884
536.2541	22.93555	27.71875
537.2375	22.93722	27.71869
538.2208	22.93011	27.71858
539.2082	22.92918	27.71858
540.1958	22.93057	27.71858
541.1791	22.93771	27.71846
542.1625	22.93486	27.71836
543.1458	22.93046	27.71828
544.1291	22.92415	27.71821
545.1209	22.92087	27.71818
546.1042	22.92178	27.71814
547.0874	22.93758	27.7181
548.0708	22.93194	27.71797
549.0541	22.925	27.71802
550.0416	22.94606	27.71784
551.0292	22.95496	27.7178
552.0125	22.95048	27.71774
552.9959	22.94697	27.71777
553.9792	22.95873	27.71766
554.9624	22.95473	27.71757
555.9541	22.95642	27.71745
556.9375	22.94477	27.71748
557.9209	22.93919	27.7174
558.9042	22.9307	27.71734
559.8875	22.9214	27.71731
560.875	22.92798	27.7172
561.8625	22.93848	27.71719
562.8458	22.9224	27.71707
563.8291	22.91524	27.71702
564.8125	22.92685	27.71698
565.7959	22.92936	27.71702
566.7875	22.9241	27.71691
567.7708	22.93122	27.7169
568.7541	22.93798	27.71678
569.7375	22.94024	27.71672
570.7208	22.93928	27.71668
571.7082	22.94514	27.71663
572.6958	22.94224	27.71659
573.6791	22.93366	27.7166
574.6625	22.92584	27.71646
575.6458	22.91533	27.71643
576.6291	22.9152	27.71639
577.6209	22.91276	27.71629
578.6042	22.91188	27.71637
579.5874	22.92016	27.71623
580.5708	22.92412	27.71625
581.5541	22.92301	27.71611
582.5416	22.92248	27.71609
583.5292	22.92996	27.71599
584.5125	22.9257	27.71599
585.4959	22.92918	27.7159
586.4791	22.92214	27.71585
587.4624	22.92746	27.71587
588.4541	22.91663	27.71576
589.4375	22.91648	27.71566
590.4209	22.92068	27.71561
591.4042	22.92414	27.71558
592.3875	22.92494	27.71544
593.375	22.9273	27.71546
594.3626	22.93014	27.71533
595.3458	22.92836	27.71533
596.3291	22.92208	27.71528
597.3125	22.91182	27.71524
598.2959	22.92727	27.71516
599.2875	22.92486	27.71516
600.2708	22.91558	27.71502
601.2541	22.91821	27.71495
602.2376	22.91758	27.715
603.2208	22.91292	27.71486
604.2082	22.90584	27.71478
605.1958	22.91759	27.71475
606.1791	22.91442	27.71463
607.1625	22.91131	27.71463
608.1458	22.90051	27.7145
609.1291	22.9002	27.71446
610.1209	22.89616	27.7144
611.1041	22.90092	27.71438
612.0874	22.9135	27.71424
613.0708	22.92372	27.71424
614.0541	22.92572	27.71405
615.0416	22.90988	27.71403
616.0292	22.89528	27.71394
617.0125	22.88904	27.71394
617.9959	22.89361	27.71383
618.9791	22.90634	27.71374
619.9624	22.88981	27.71372
620.9541	22.89419	27.7136
621.9375	22.89614	27.71355
622.9209	22.89093	27.71346
623.9042	22.89538	27.71344
624.8875	22.91349	27.71346
625.875	22.90869	27.71332
626.8626	22.89475	27.71322
627.8458	22.89885	27.71314
628.8291	22.90765	27.71308
629.8125	22.9036	27.71309
630.7959	22.90389	27.71309
631.7875	22.91914	27.71304
632.7708	22.90746	27.7129
633.7541	22.8808	27.71289
634.7376	22.89502	27.7128
635.7208	22.90064	27.71272
636.7082	22.91	27.71268
637.6958	22.91172	27.71265
638.6791	22.91019	27.7126
639.6625	22.89972	27.7126
640.6458	22.88873	27.71249
641.6291	22.89202	27.71239
642.6209	22.89689	27.7125
643.6041	22.91144	27.71248
644.5874	22.90657	27.71239
645.5708	22.89636	27.71235
646.5541	22.90361	27.71226
647.5416	22.91406	27.71224
648.5292	22.91786	27.71213
649.5125	22.91423	27.71215
650.4959	22.90652	27.71212
651.4791	22.9042	27.71215
652.4624	22.90261	27.71209
653.4541	22.90661	27.71204
654.4375	22.90537	27.7121
655.4209	22.90502	27.71201
656.4042	22.91567	27.71201
657.3875	22.91694	27.71191
658.375	22.92192	27.71194
659.3626	22.91575	27.71187
660.3458	22.90837	27.7119
661.329	22.893	27.71182
662.3125	22.89059	27.71178
663.2959	22.88791	27.71173
664.2875	22.90244	27.71168
665.2708	22.92473	27.71164
666.2541	22.92363	27.71161
667.2376	22.91532	27.7115
668.2208	22.91936	27.71148
669.2082	22.90689	27.71144
670.1958	22.89742	27.7114
671.1791	22.88975	27.71145
672.1625	22.90496	27.71134
673.1458	22.90639	27.71132
674.1291	22.89516	27.7113
675.1209	22.88944	27.71128
676.104	22.88756	27.71118
677.0874	22.88737	27.71125
678.0708	22.89348	27.71112
679.0541	22.89987	27.71116
680.0416	22.90258	27.71104
681.0292	22.91009	27.71104
682.0125	22.91473	27.71099
682.996	22.9182	27.71095
683.979	22.91004	27.71096
684.9624	22.89775	27.7109
685.954	22.89792	27.71086
686.9375	22.8949	27.71086
687.9209	22.88614	27.71074
688.9042	22.87976	27.71074
689.8875	22.87942	27.71072
690.875	22.88152	27.71062
691.8626	22.87844	27.71064
692.8457	22.8698	27.71058
693.829	22.87755	27.71057
694.8125	22.88844	27.71051
695.7959	22.88872	27.71045
696.7875	22.90232	27.71044
697.7708	22.9092	27.71042
698.7542	22.9097	27.71033
699.7376	22.90169	27.71032
700.7207	22.88516	27.7103
701.7082	22.86949	27.71026
702.6958	22.88094	27.71016
703.6791	22.89297	27.71012
704.6625	22.90191	27.71017
705.6458	22.8813	27.71006
706.6292	22.88838	27.70994
707.621	22.89106	27.70992
708.604	22.87937	27.70988
709.5874	22.87881	27.7098
710.5708	22.88481	27.70978
711.5541	22.88781	27.7098
712.5416	22.87813	27.70976
713.5292	22.87893	27.70967
714.5125	22.87851	27.70969
715.496	22.8809	27.70956
716.479	22.88368	27.70963
717.4624	22.89044	27.70949
718.454	22.90136	27.70946
719.4375	22.90573	27.70948
720.4209	22.90132	27.70939
721.4042	22.89236	27.7093
722.3875	22.88472	27.70926
723.375	22.88446	27.70926
724.3626	22.88312	27.70916
725.3457	22.88646	27.70919
726.329	22.88566	27.70906
727.3125	22.8918	27.70902
728.2959	22.87375	27.70904
729.2875	22.85999	27.70898
730.2708	22.8498	27.70889
731.2542	22.85789	27.70888
732.2376	22.87394	27.70881
733.2207	22.8782	27.70883
734.2082	22.87566	27.70867
735.1958	22.8744	27.70869
736.1791	22.86314	27.7086
737.1625	22.87148	27.7086
738.1458	22.8678	27.70859
739.1292	22.87012	27.7086
740.121	22.87393	27.70832
741.104	22.86781	27.70836
742.0874	22.8688	27.70846
743.0708	22.86484	27.70836
744.0541	22.86459	27.70836
745.0416	22.86058	27.70824
746.0292	22.86477	27.70818
747.0125	22.87794	27.70817
747.996	22.88119	27.70804
748.979	22.87947	27.70806
749.9624	22.87772	27.70804
750.954	22.88393	27.70796
751.9375	22.87766	27.70785
752.9209	22.87067	27.70792
753.9042	22.87442	27.70786
754.8875	22.8761	27.70777
755.875	22.8709	27.70771
756.8626	22.86251	27.70769
757.8457	22.874	27.70764
758.829	22.87442	27.7076
759.8125	22.87752	27.70757
760.7959	22.8591	27.70757
761.7875	22.85871	27.7074
762.7708	22.8635	27.70744
763.7542	22.85653	27.70744
764.7376	22.8631	27.70736
765.7207	22.88016	27.7073
766.7082	22.87896	27.70728
767.6958	22.8861	27.7073
768.6791	22.88162	27.70721
769.6625	22.8848	27.70718
770.6458	22.88877	27.70714
771.6292	22.88655	27.70711
772.621	22.86839	27.70708
773.604	22.86208	27.70707
774.5874	22.8639	27.70694
775.5708	22.8678	27.70692
776.5541	22.86356	27.70692
777.5416	22.86428	27.70682
778.5292	22.85716	27.70687
779.5125	22.86844	27.70668
780.496	22.87219	27.70668
781.479	22.87469	27.70661
782.4624	22.86306	27.70654
783.454	22.85913	27.7065
784.4375	22.8588	27.70654
785.4209	22.86729	27.70649
786.4042	22.87453	27.7065
787.3875	22.85711	27.70646
788.375	22.85011	27.70637
789.3626	22.85394	27.70639
790.3457	22.87688	27.70632
791.329	22.88023	27.7063
792.3125	22.87381	27.70626
793.2959	22.86482	27.7062
794.2875	22.8443	27.70618
795.2708	22.84682	27.70616
796.2542	22.86529	27.7061
797.2376	22.8694	27.7061
798.2207	22.87246	27.70615
799.2082	22.87348	27.70604
800.1958	22.88243	27.70604
801.1791	22.8926	27.70596
802.1625	22.87294	27.70593
803.1458	22.8592	27.70583
804.1292	22.8574	27.70586
805.121	22.85519	27.70583
806.104	22.85039	27.70579
807.0874	22.85189	27.70574
808.0708	22.86437	27.70577
809.0541	22.86939	27.70573
810.0416	22.85434	27.70561
811.0292	22.8566	27.70557
812.0125	22.85458	27.7057
812.996	22.8685	27.70559
813.979	22.86696	27.70555
814.9624	22.85588	27.70549
815.954	22.85388	27.70549
816.9375	22.85117	27.70546
817.9209	22.847	27.70543
818.9042	22.86148	27.70538
819.8875	22.87256	27.7053
820.875	22.87984	27.70532
821.8625	22.86918	27.70538
822.8457	22.86775	27.70527
823.829	22.86017	27.70527
824.8125	22.85577	27.70522
825.7958	22.87102	27.70512
826.7875	22.87793	27.70515
827.771	22.87354	27.70512
828.7542	22.86363	27.70508
829.7375	22.85037	27.70504
830.7207	22.84555	27.70503
831.7082	22.8532	27.70496
832.6958	22.86296	27.70492
833.679	22.86006	27.70491
834.6625	22.85887	27.70483
835.646	22.85693	27.70484
836.6292	22.85423	27.70474
837.621	22.85308	27.70474
838.604	22.85093	27.70474
839.5874	22.85433	27.70469
840.5708	22.84964	27.70462
841.5541	22.84839	27.70468
842.5416	22.85599	27.70466
843.5292	22.8459	27.70457
844.5125	22.84802	27.7045
845.4959	22.84644	27.70449
846.4791	22.85079	27.70448
847.4624	22.84599	27.70446
848.4541	22.86281	27.70442
849.4375	22.86833	27.7044
850.4208	22.85671	27.70433
851.4042	22.85278	27.70425
852.3875	22.85982	27.70426
853.3751	22.86226	27.7043
854.3625	22.85296	27.70418
855.3457	22.83843	27.70419
856.3291	22.84747	27.70412
857.3125	22.84556	27.70403
858.2958	22.84538	27.70403
859.2875	22.84725	27.70402
860.2709	22.86057	27.70391
861.2542	22.86363	27.70391
862.2375	22.86268	27.70388
863.2207	22.86826	27.70387
864.2082	22.86853	27.7039
865.1958	22.85348	27.70378
866.1791	22.84656	27.7038
867.1625	22.84188	27.70368
868.1459	22.84566	27.70369
869.1292	22.84871	27.70366
870.1209	22.848	27.70368
871.1041	22.85202	27.70354
872.0874	22.85162	27.70358
873.0708	22.82884	27.70354
874.0541	22.82446	27.70345
875.0416	22.83072	27.70344
876.0292	22.83826	27.70342
877.0125	22.85242	27.70344
877.9959	22.84992	27.70332
878.9791	22.84586	27.70337
879.9624	22.83627	27.7033
880.9541	22.84708	27.70324
881.9375	22.8483	27.7032
882.9208	22.84656	27.70316
883.9042	22.85332	27.70311
884.8875	22.8426	27.70308
885.8751	22.8463	27.70309
886.8625	22.84848	27.70308
887.8457	22.85935	27.70307
888.8291	22.87098	27.70297
889.8125	22.8583	27.70298
890.7958	22.83258	27.7029
891.7875	22.82167	27.7029
892.7709	22.82629	27.70286
893.7542	22.84845	27.70274
894.7375	22.85404	27.7027
895.7207	22.84554	27.70274
896.7082	22.83261	27.7027
897.6958	22.82752	27.70264
898.6791	22.83403	27.70257
899.6625	22.84035	27.70256
900.6459	22.84628	27.70261
901.6292	22.85437	27.70246
902.6209	22.84194	27.7025
903.6041	22.84555	27.70243
904.5874	22.84713	27.70231
905.5708	22.84178	27.7024
906.5541	22.84434	27.70238
907.5416	22.83454	27.70231
908.5292	22.84243	27.70222
909.5125	22.83626	27.70227
910.4959	22.84399	27.70222
911.4791	22.84943	27.70222
912.4624	22.84277	27.70215
913.4541	22.84732	27.70212
914.4375	22.85738	27.70208
915.4208	22.86148	27.70204
916.4042	22.84832	27.70203
917.3875	22.82936	27.70199
918.3751	22.82094	27.70196
919.3625	22.82822	27.70196
920.3457	22.83704	27.70195
921.3291	22.83685	27.70187
922.3125	22.83688	27.70189
923.2958	22.83006	27.70182
924.2875	22.83147	27.70176
925.2709	22.84422	27.70176
926.2542	22.85512	27.70173
927.2375	22.85242	27.70168
928.2207	22.84275	27.70164
929.2082	22.83564	27.70165
930.1958	22.83798	27.70164
931.1791	22.83675	27.70163
932.1625	22.84894	27.70159
933.1459	22.84819	27.70159
934.1292	22.83064	27.70147
935.1209	22.83185	27.70146
936.1041	22.83364	27.70142
937.0874	22.84161	27.70137
938.0708	22.82858	27.70139
939.0541	22.82073	27.70139
940.0418	22.8203	27.70133
941.0292	22.8212	27.70127
942.0125	22.81831	27.7013
942.9959	22.83442	27.70124
943.9791	22.83688	27.70128
944.9624	22.84066	27.7011
945.9541	22.83944	27.70115
946.9375	22.83676	27.70115
947.9208	22.83125	27.7011
948.9042	22.83519	27.70118
949.8875	22.82596	27.70118
950.8751	22.81524	27.70102
951.8625	22.81805	27.70098
952.8457	22.81144	27.70093
953.8291	22.82166	27.70096
954.8125	22.81665	27.70098
955.7958	22.80757	27.70092
956.7875	22.82054	27.70086
957.7709	22.83701	27.70086
958.7542	22.83219	27.7008
959.7375	22.8267	27.70079
960.7207	22.84168	27.70072
961.7082	22.84041	27.70074
962.6958	22.8509	27.70075
963.6791	22.85379	27.7007
964.6625	22.85497	27.70068
965.6459	22.84852	27.70064
966.6292	22.82075	27.70062
967.6209	22.82212	27.70055
968.6041	22.8246	27.70058
969.5874	22.82802	27.70055
970.5708	22.83609	27.70045
971.5541	22.84812	27.70049
972.5418	22.84534	27.70047
973.5292	22.82877	27.70041
974.5125	22.83025	27.70041
975.4959	22.8378	27.70049
976.4791	22.84597	27.70038
977.4624	22.83458	27.70026
978.4541	22.83459	27.70032
979.4375	22.83348	27.70038
980.4208	22.83348	27.70024
981.4042	22.83684	27.70022
982.3875	22.82848	27.70024
983.3751	22.82684	27.70022
984.3625	22.84074	27.70021
985.3457	22.83563	27.70022
986.3291	22.84646	27.70011
987.3125	22.85342	27.70016
988.2958	22.84775	27.70014
989.2875	22.83494	27.70012
990.2709	22.82597	27.7001
991.2542	22.82881	27.70001
992.2375	22.82854	27.7
993.2207	22.83041	27.70002
994.2082	22.83169	27.7
995.1958	22.82999	27.70005
996.1791	22.81622	27.70002
997.1625	22.81983	27.69996
998.1459	22.82894	27.69992
999.1292	22.82472	27.6999
1000.121	22.83719	27.69988
1001.104	22.84805	27.69985
1002.087	22.84842	27.6999
1003.071	22.85828	27.69988
1004.054	22.84805	27.69985
1005.042	22.84209	27.69988
1006.029	22.83338	27.69987
1007.012	22.8247	27.69983
1007.996	22.82694	27.6998
1008.979	22.82922	27.69978
1009.962	22.82084	27.69973
1010.954	22.81522	27.69974
1011.938	22.82281	27.69976
1012.921	22.83555	27.69974
1013.904	22.83234	27.69962
1014.888	22.83099	27.69962
1015.875	22.82817	27.69956
1016.862	22.81598	27.69954
1017.846	22.81443	27.69954
1018.829	22.82411	27.69952
1019.812	22.82007	27.69949
1020.796	22.81906	27.69945
1021.788	22.832	27.69949
1022.771	22.82788	27.69948
1023.754	22.81579	27.69946
1024.738	22.80994	27.69936
1025.721	22.80907	27.6994
1026.708	22.81572	27.6994
1027.696	22.82961	27.6994
1028.679	22.82046	27.69934
1029.663	22.81429	27.69934
1030.646	22.80982	27.69928
1031.629	22.80708	27.69928
1032.621	22.80435	27.6993
1033.604	22.79747	27.69922
1034.587	22.8006	27.69916
1035.571	22.79631	27.69916
1036.554	22.7974	27.69908
1037.542	22.80127	27.6991
1038.529	22.80194	27.69916
1039.513	22.80119	27.69916
1040.496	22.80756	27.69902
1041.479	22.80727	27.69905
1042.462	22.79547	27.69903
1043.454	22.79534	27.69899
1044.438	22.7962	27.69892
1045.421	22.8107	27.69899
1046.404	22.81164	27.69896
1047.388	22.80539	27.69889
1048.375	22.79897	27.69886
1049.362	22.78752	27.69878
1050.346	22.78859	27.69878
1051.329	22.80852	27.69878
1052.312	22.82278	27.69877
1053.296	22.80953	27.69878
1054.288	22.792	27.69876
1055.271	22.79816	27.69874
1056.254	22.8043	27.6987
1057.238	22.81316	27.69876
1058.221	22.81316	27.69864
1059.208	22.80157	27.69874
1060.196	22.7982	27.69868
1061.179	22.8012	27.69859
1062.163	22.80711	27.69859
1063.146	22.80476	27.69855
1064.129	22.79038	27.69849
1065.121	22.78422	27.69846
1066.104	22.80112	27.69846
1067.087	22.80629	27.69848
1068.071	22.80586	27.69844
1069.054	22.8106	27.69832
1070.042	22.81165	27.69831
1071.029	22.8011	27.6983
1072.013	22.79482	27.69834
1072.996	22.7973	27.69824
1073.979	22.80218	27.6982
1074.962	22.79037	27.69824
1075.954	22.7946	27.69819
1076.938	22.79696	27.69812
1077.921	22.79994	27.6982
1078.904	22.80105	27.69807
1079.888	22.80489	27.69813
1080.875	22.80232	27.69805
1081.862	22.80394	27.69803
1082.846	22.80498	27.69809
1083.829	22.80007	27.69803
1084.812	22.79984	27.698
1085.796	22.79253	27.698
1086.788	22.79432	27.69796
1087.771	22.79647	27.69798
1088.754	22.80604	27.69784
1089.738	22.80258	27.69794
1090.721	22.79784	27.69788
1091.708	22.78895	27.69792
1092.696	22.78826	27.69787
1093.679	22.78285	27.6978
1094.663	22.79816	27.69781
1095.646	22.80064	27.69778
1096.629	22.81104	27.69778
1097.621	22.80031	27.69768
1098.604	22.79344	27.69771
1099.587	22.78346	27.69775
1100.571	22.78996	27.69762
1101.554	22.81117	27.69761
1102.542	22.81317	27.69763
1103.529	22.81428	27.69755
1104.513	22.80116	27.6976
1105.496	22.79829	27.69754
1106.479	22.78565	27.69761
1107.462	22.78616	27.69755
1108.454	22.79872	27.69746
1109.438	22.79485	27.69746
1110.421	22.79325	27.69744
1111.404	22.79312	27.69742
1112.388	22.79471	27.69744
1113.375	22.78322	27.6974
1114.362	22.7777	27.6974
1115.346	22.78986	27.69734
1116.329	22.80282	27.69729
1117.312	22.80904	27.69732
1118.296	22.80439	27.69733
1119.288	22.80037	27.6973
1120.271	22.78402	27.69726
1121.254	22.77531	27.69724
1122.238	22.80299	27.69719
1123.221	22.8074	27.69716
1124.208	22.79338	27.69718
1125.196	22.78742	27.69714
1126.179	22.79753	27.69715
1127.163	22.79092	27.69713
1128.146	22.78455	27.69709
1129.129	22.79814	27.69707
1130.121	22.7928	27.69704
1131.104	22.79433	27.697
1132.087	22.7943	27.69692
1133.071	22.79218	27.69702
1134.054	22.78614	27.69692
1135.042	22.79832	27.69683
1136.029	22.79863	27.69686
1137.013	22.80337	27.69689
1137.996	22.79038	27.69684
1138.979	22.79394	27.69683
1139.962	22.78906	27.69676
1140.954	22.7815	27.69674
1141.938	22.78732	27.69675
1142.921	22.7919	27.69678
1143.904	22.7862	27.69667
1144.888	22.79378	27.69672
1145.875	22.78408	27.69669
1146.862	22.782	27.69661
1147.846	22.78551	27.69663
1148.829	22.79697	27.69668
1149.812	22.79356	27.69664
1150.796	22.77924	27.69655
1151.788	22.78301	27.69651
1152.771	22.7952	27.6965
1153.754	22.80264	27.69651
1154.738	22.81092	27.69648
1155.721	22.81156	27.6965
1156.708	22.81382	27.6965
1157.696	22.80904	27.69646
1158.679	22.81285	27.69644
1159.663	22.80492	27.69643
1160.646	22.79709	27.69645
1161.629	22.79746	27.69646
1162.621	22.80154	27.69629
1163.604	22.8018	27.69636
1164.587	22.81013	27.69635
1165.571	22.80201	27.69629
1166.554	22.79176	27.69626
1167.542	22.80628	27.69622
1168.529	22.80772	27.69634
1169.513	22.81044	27.69626
1170.496	22.80898	27.6962
1171.479	22.80188	27.69619
1172.462	22.80323	27.69622
1173.454	22.80939	27.6961
1174.438	22.8083	27.69612
1175.421	22.81844	27.69611
1176.404	22.81715	27.69602
1177.388	22.81012	27.69618
1178.375	22.80234	27.69606
1179.362	22.79782	27.69604
1180.346	22.79704	27.69597
1181.329	22.79944	27.69601
1182.312	22.81772	27.69594
1183.296	22.82848	27.69599
1184.288	22.82058	27.69592
1185.271	22.79808	27.69584
1186.254	22.79088	27.69582
1187.238	22.80728	27.69584
1188.221	22.80627	27.69588
1189.208	22.79698	27.69589
1190.196	22.79444	27.69585
1191.179	22.798	27.69582
1192.163	22.80139	27.6958
1193.146	22.8052	27.6957
1194.129	22.80701	27.69574
1195.121	22.80037	27.69578
1196.104	22.7938	27.69573
1197.087	22.79289	27.6957
1198.071	22.79082	27.69572
1199.054	22.79178	27.69569
1200.042	22.80217	27.69564
1201.029	22.81361	27.69566
1202.012	22.81526	27.69561
1202.996	22.81063	27.69554
1203.979	22.8055	27.69563
1204.962	22.81254	27.6956
1205.954	22.7986	27.69554
1206.938	22.79246	27.69554
1207.921	22.7972	27.69549
1208.904	22.79562	27.69551
1209.888	22.8095	27.69554
1210.875	22.79064	27.69554
1211.862	22.80022	27.69547
1212.846	22.8146	27.69549
1213.829	22.8068	27.69548
1214.812	22.79828	27.69541
1215.796	22.78947	27.6954
1216.788	22.78974	27.69539
1217.771	22.78538	27.69536
1218.754	22.7965	27.69535
1219.738	22.79103	27.69536
1220.721	22.79513	27.69536
1221.708	22.82572	27.6953
1222.696	22.83189	27.69536
1223.679	22.81576	27.69537
1224.663	22.80058	27.6952
1225.646	22.80409	27.69524
1226.629	22.80563	27.69526
1227.621	22.81249	27.69525
1228.604	22.8085	27.69524
1229.587	22.79398	27.69527
1230.571	22.80632	27.69522
1231.554	22.80368	27.69522
1232.542	22.8067	27.69522
1233.529	22.81569	27.69514
1234.512	22.82204	27.69518
1235.496	22.81086	27.69515
1236.479	22.80728	27.69519
1237.462	22.80156	27.69518
1238.454	22.8	27.6951
1239.438	22.79848	27.69514
1240.421	22.78948	27.69515
1241.404	22.78218	27.69517
1242.388	22.78751	27.69504
1243.375	22.7857	27.69508
1244.362	22.79251	27.69504
1245.346	22.8006	27.69502
1246.329	22.80602	27.69502
1247.312	22.80854	27.69497
1248.296	22.81185	27.695
1249.288	22.80363	27.69501
1250.271	22.79343	27.69498
1251.254	22.80173	27.69492
1252.238	22.81456	27.69492
1253.221	22.8068	27.69494
1254.208	22.79932	27.69492
1255.196	22.79292	27.69494
1256.179	22.79638	27.69484
1257.163	22.7905	27.69488
1258.146	22.77932	27.69482
1259.129	22.7814	27.69474
1260.121	22.79885	27.69479
1261.104	22.80397	27.69476
1262.087	22.80371	27.69484
1263.071	22.78342	27.69475
1264.054	22.79988	27.69471
1265.042	22.81209	27.69478
1266.029	22.8132	27.69467
1267.012	22.80076	27.69471
1267.996	22.81295	27.69463
1268.979	22.79327	27.69463
1269.962	22.78617	27.69458
1270.954	22.79109	27.69462
1271.938	22.78654	27.69456
1272.921	22.78543	27.69461
1273.904	22.78486	27.6946
1274.888	22.78336	27.69463
1275.875	22.80282	27.69456
1276.862	22.811	27.69454
1277.846	22.81289	27.69444
1278.829	22.79538	27.6945
1279.812	22.77204	27.69457
1280.796	22.76702	27.69442
1281.788	22.78298	27.69446
1282.771	22.78875	27.69446
1283.754	22.78304	27.69439
1284.738	22.791	27.69437
1285.721	22.79096	27.69439
1286.708	22.78777	27.69436
1287.696	22.79389	27.69432
1288.679	22.80278	27.6943
1289.663	22.79836	27.69428
1290.646	22.7973	27.69426
1291.629	22.79268	27.6942
1292.621	22.78014	27.69425
1293.604	22.77908	27.69414
1294.587	22.77984	27.6943
1295.571	22.79449	27.69419
1296.554	22.80858	27.6942
1297.542	22.80505	27.69418
1298.529	22.79455	27.69409
1299.512	22.78827	27.69405
1300.496	22.78314	27.69406
1301.479	22.7951	27.69406
1302.462	22.8083	27.69406
1303.454	22.80108	27.69402
1304.438	22.79078	27.6939
1305.421	22.7881	27.69398
1306.404	22.78316	27.69392
1307.388	22.7962	27.69398
1308.375	22.78452	27.69397
1309.362	22.79019	27.69383
1310.346	22.8026	27.69391
1311.329	22.80469	27.69384
1312.312	22.80806	27.69391
1313.296	22.80998	27.69387
1314.288	22.79722	27.69385
1315.271	22.79189	27.69383
1316.254	22.7829	27.69379
1317.238	22.78424	27.69379
1318.221	22.7931	27.6938
1319.208	22.8159	27.69372
1320.196	22.8033	27.69374
1321.179	22.79575	27.69362
1322.163	22.77111	27.69371
1323.146	22.77506	27.69375
1324.129	22.78934	27.69366
1325.121	22.78946	27.69364
1326.104	22.78318	27.69366
1327.087	22.7773	27.69357
1328.071	22.78625	27.69357
1329.054	22.80153	27.6936
1330.042	22.806	27.69365
1331.029	22.79442	27.69355
1332.012	22.79498	27.6936
1332.996	22.79316	27.69351
1333.979	22.78484	27.69352
1334.962	22.77724	27.69344
1335.954	22.78516	27.69344
1336.938	22.78317	27.69342
1337.921	22.7726	27.6934
1338.904	22.78464	27.69336
1339.888	22.78106	27.69344
1340.875	22.78923	27.69341
1341.862	22.79192	27.69341
1342.846	22.79207	27.69338
1343.829	22.78898	27.69336
1344.812	22.78183	27.69328
1345.796	22.78623	27.69335
1346.788	22.7792	27.6933
1347.771	22.7886	27.69331
1348.754	22.78397	27.69326
1349.738	22.78138	27.69326
1350.721	22.7687	27.69318
1351.708	22.77136	27.69316
1352.696	22.7832	27.69313
1353.679	22.77968	27.6932
1354.663	22.78262	27.69315
1355.646	22.7987	27.69319
1356.629	22.80201	27.69305
1357.621	22.80001	27.69304
1358.604	22.80736	27.69305
1359.587	22.7817	27.69311
1360.571	22.77619	27.69299
1361.554	22.77657	27.69294
1362.542	22.79622	27.69294
1363.529	22.7959	27.69294
1364.512	22.79462	27.693
1365.496	22.80272	27.69294
1366.479	22.79605	27.69296
1367.462	22.78074	27.69292
1368.454	22.78876	27.69293
1369.438	22.78796	27.69284
1370.421	22.7857	27.69278
1371.404	22.78499	27.69285
1372.388	22.77997	27.69279
1373.375	22.77134	27.69271
1374.362	22.76997	27.69269
1375.346	22.77469	27.69283
1376.329	22.77423	27.6928
1377.312	22.76982	27.69274
1378.296	22.75811	27.69268
1379.288	22.76916	27.69268
1380.271	22.79453	27.69264
1381.254	22.79032	27.69263
1382.238	22.77805	27.6926
1383.221	22.77164	27.69254
1384.208	22.75889	27.6926
1385.196	22.76513	27.69246
1386.179	22.7633	27.69254
1387.163	22.774	27.6924
1388.146	22.76991	27.69235
1389.129	22.77059	27.69239
1390.121	22.76493	27.6924
1391.104	22.76407	27.69221
1392.088	22.76444	27.69226
1393.071	22.76337	27.69209
1394.054	22.76464	27.69216
1395.042	22.76986	27.69208
1396.029	22.75592	27.69204
1397.012	22.76121	27.69191
1397.996	22.75472	27.69191
1398.979	22.7443	27.69184
1399.962	22.75041	27.69164
1400.954	22.7466	27.69173
1401.938	22.75249	27.69162
1402.921	22.76308	27.69151
1403.904	22.76176	27.69143
1404.888	22.75148	27.69135
1405.875	22.74904	27.69132
1406.862	22.74948	27.6907
1407.846	22.76558	27.69033
1408.829	22.77631	27.69074
1409.812	22.75596	27.69088
1410.796	22.75485	27.69079
1411.788	22.76148	27.6908
1412.771	22.755	27.69066
1413.754	22.74961	27.69074
1414.738	22.74696	27.6906
1415.721	22.75248	27.69056
1416.708	22.74532	27.69044
1417.696	22.76162	27.69047
1418.679	22.75547	27.69043
1419.663	22.76024	27.69033
1420.646	22.76356	27.69027
1421.629	22.76516	27.69019
1422.621	22.76072	27.69012
1423.604	22.75132	27.69008
1424.588	22.76039	27.69003
1425.571	22.76724	27.68996
1426.554	22.7682	27.68992
1427.542	22.77144	27.6899
1428.529	22.77051	27.68992
1429.512	22.74784	27.68981
1430.496	22.7407	27.68978
1431.479	22.73941	27.68966
1432.462	22.743	27.68968
1433.454	22.75361	27.68954
1434.438	22.75645	27.68948
1435.421	22.75994	27.68954
1436.404	22.74896	27.6894
1437.388	22.74868	27.6894
1438.375	22.74508	27.68262
1439.362	22.75322	27.68256
1439.888	22.74974	27.68255